Workbook
Name Alternativas_nombres: Configuracion!$E$13:$E$20
Name Criterios_nombres: Configuracion!$C$13:$C$20
Name nA: Configuracion!$D$8
Name nC: Configuracion!$D$7
Name RI_tabla: Instrucciones!$C$42:$C$51

Sheet Instrucciones
B2: Calculadora AHP · Proceso Analitico Jerarquico (Saaty)
B3: Compara criterios y alternativas de a dos, calcula los pesos y verifica la coherencia de tus juicios con la Razon de Consistencia (CR).
B5: COMO SE USA ESTE ARCHIVO
B6: 1 | C6: Hoja CONFIGURACION | D6: Escribe cuantos criterios y cuantas alternativas vas a usar (de 2 a 8) y ponles nombre. Todo lo demas se ajusta solo.
B7: 2 | C7: Hoja CRITERIOS | D7: Compara los criterios entre si. Solo llenas las celdas amarillas (la mitad de arriba): el resto se calcula solo porque la matriz es reciproca.
B8: 3 | C8: Hojas C1, C2, C3 ... | D8: Una hoja por criterio. En cada una comparas las ALTERNATIVAS entre si, pero mirando SOLO ese criterio. Si usas 3 criterios, solo llenas C1, C2 y C3.
B9: 4 | C9: Revisa el CR de cada hoja | D9: Cada hoja te dice su Razon de Consistencia en porcentaje. Si es 10% o menos, vas bien. Si pasa de 10%, tus comparaciones se contradicen y hay que corregirlas.
B10: 5 | C10: Hoja RESULTADO | D10: Te muestra el peso de cada criterio, la puntuacion final de cada alternativa, el ranking y si puedes tomar la decision o te toca reevaluar.
B12: LA ESCALA DE SAATY · que numero escribir en cada celda
B13: Siempre te preguntas lo mismo: comparando el elemento de la FILA con el de la COLUMNA, ¿cual es mas importante y cuanto mas?
B14: Valor | C14: Significado | D14: Como saber si es este | E14: Ejemplo para que te quede claro
B15: 1 | C15: Igual importancia | D15: Los dos aportan lo mismo a la decision. Te daria igual perder uno u otro. | E15: Para elegir un portatil: 'el peso y el color me dan exactamente igual'.
B16: 3 | C16: Moderadamente mas importante | D16: Uno pesa un poco mas, pero si el otro gana no es un desastre. Dudas al responder. | E16: 'El precio me importa algo mas que el diseno, pero no mucho mas'.
B17: 5 | C17: Fuertemente mas importante | D17: Tienes clara la preferencia y la puedes justificar sin pensarlo. | E17: 'La seguridad importa bastante mas que la personalizacion'.
B18: 7 | C18: Muy fuertemente mas importante | D18: La preferencia es evidente para cualquiera del equipo, no solo para ti. | E18: 'Cumplir la ley importa muchisimo mas que ahorrar dos dias'.
B19: 9 | C19: Extremadamente mas importante | D19: El otro criterio casi no cuenta al lado de este. Es el maximo de la escala. | E19: 'Que no se pierdan los datos del banco frente a que la pantalla sea bonita'.
B20: 2, 4, 6, 8 | C20: Valores intermedios | D20: Usalos solo cuando dudas entre dos escalones de los de arriba. | E20: 'Es mas que moderado pero no llega a fuerte' -> pon 4.
B22: ¿Y SI EL DE LA COLUMNA ES EL MAS IMPORTANTE? · los reciprocos
B23: Entonces escribes la fraccion invertida. En Excel escribela como formula: =1/3 , =1/5 , =1/7 ... La celda te la va a mostrar como 1/3, 1/5, 1/7. Y OJO: nunca escribas 1/3 sin el signo igual, porque Excel lo entiende como una fecha.
B25: Si pones 5 en (Seguridad , Costo) | D25: quiere decir: la seguridad es fuertemente mas importante que el costo.
B26: Si pones =1/5 en (Seguridad , Costo) | D26: quiere decir lo contrario: el costo es fuertemente mas importante.
B27: La diagonal siempre vale 1 | D27: porque comparar algo consigo mismo da igualdad.
B28: La mitad de abajo se llena sola | D28: es el inverso de la de arriba. Por eso solo llenas las celdas amarillas.
B30: LA RAZON DE CONSISTENCIA (CR) · como leer el porcentaje
B31: El AHP no solo calcula la respuesta: tambien revisa si tus juicios se contradicen entre si. El ejemplo clasico de contradiccion es decir que A es mejor que B, que B es mejor que C, y ademas que C es mejor que A. Eso es imposible, y el CR lo detecta.
B33: CR = 0% | D33: Coherencia perfecta. Tus comparaciones encajan a la perfeccion.
B34: CR hasta 10% | D34: ACEPTABLE. Puedes usar el resultado con tranquilidad.
B35: CR entre 10% y 20% | D35: DUDOSO. Revisa las comparaciones mas extremas antes de decidir.
B36: CR mayor a 20% | D36: RECHAZADO. Hay que reevaluar: tus juicios se contradicen demasiado.
B38: Si te sale mal: busca en la matriz el numero mas extremo (un 7 o un 9) y pregunta si de verdad es para tanto. Casi siempre el problema esta ahi. Baja ese juicio un escalon y vuelve a mirar el CR.
B40: INDICE ALEATORIO (RI) · valores de Saaty, no los toques
B41: n (elementos) | C41: RI | D41: Formulas que usa el archivo
B42: 1 | C42: 0 | D42: Vector de prioridad w = promedio de cada fila de la matriz normalizada
B43: 2 | C43: 0 | D43: lambda max = promedio de (A·w) dividido w, elemento por elemento
B44: 3 | C44: 0.58 | D44: CI (indice de consistencia) = (lambda max - n) / (n - 1)
B45: 4 | C45: 0.9 | D45: CR (razon de consistencia) = CI / RI
B46: 5 | C46: 1.12 | D46: Se acepta cuando CR <= 0,10 (es decir, 10%)
B47: 6 | C47: 1.24 | D47: Puntuacion final de cada alternativa = suma de (peso del criterio x prioridad en ese criterio)
B48: 7 | C48: 1.32
B49: 8 | C49: 1.41
...

Sheet Configuracion
B2: Paso 0 · Define tu problema
B3: Escribe aqui tu decision, tus criterios y tus alternativas. Las demas hojas se ajustan solas.
B5: Decision que voy a tomar: | C5: Elegir el motor de base de datos para la plataforma financiera
B7: Cuantos CRITERIOS voy a usar: | D7: 5 | E7: de 2 a 8
B8: Cuantas ALTERNATIVAS voy a comparar: | D8: 3 | E8: de 2 a 8
B10: Recomendacion de Saaty: no pases de 7 u 8 elementos en una misma comparacion. Con mas, el cerebro humano pierde coherencia y el CR se dispara.
B12: N.º | C12: CRITERIOS · que importa al decidir | D12: N.º | E12: ALTERNATIVAS · entre que elijo
B13: 1 | C13: Costo total | D13: 1 | E13: Nativas
B14: 2 | C14: Tiempo de entrega | D14: 2 | E14: Multiplataforma
B15: 3 | C15: Experiencia de usario | D15: 3 | E15: Aplicación web
B16: 4 | C16: Funciona sin internet | D16: 4
B17: 5 | C17: Seguridad | D17: 5
B18: 6 | C18: Acceso a Hardware | D18: 6
B19: 7 | C19: Función sin internet | D19: 7
B20: 8 | C20: Curva de aprendisaje del equipo | D20: 8
B22: QUE HACER AHORA
B23: 1. Ve a la hoja CRITERIOS y compara los criterios entre si.
B24: 2. Luego llena una hoja C1, C2, C3... por cada criterio que hayas definido.
B25: 3. Termina en la hoja RESULTADO.
B27: El archivo viene con un ejemplo cargado (el caso de la base de datos). Borra los nombres y los numeros y escribe los tuyos.

Sheet Criterios
B2: Paso 1 · Comparacion de los CRITERIOS entre si
B3: Pregunta para cada celda amarilla: comparando el criterio de la FILA con el de la COLUMNA, ¿cual importa mas y cuanto mas? (1, 3, 5, 7, 9 o su inverso =1/3, =1/5 ...).
B5: PASO 1 · Matriz de comparacion por pares (llena SOLO las celdas amarillas) | L5: ESCALA | M5: Cuando usarla
B6: FILA \ COLUMNA | C6: =IF(1>nC,"",INDEX(Configuracion!$C$13:$C$20,1)) -> Costo total | D6: =IF(2>nC,"",INDEX(Configuracion!$C$13:$C$20,2)) -> Tiempo de entrega | E6: =IF(3>nC,"",INDEX(Configuracion!$C$13:$C$20,3)) -> Experiencia de usario | F6: =IF(4>nC,"",INDEX(Configuracion!$C$13:$C$20,4)) -> Funciona sin internet | G6: =IF(5>nC,"",INDEX(Configuracion!$C$13:$C$20,5)) -> Seguridad | H6: =IF(6>nC,"",INDEX(Configuracion!$C$13:$C$20,6)) | I6: =IF(7>nC,"",INDEX(Configuracion!$C$13:$C$20,7)) | J6: =IF(8>nC,"",INDEX(Configuracion!$C$13:$C$20,8)) | L6: 1 | M6: Los dos importan igual
B7: =IF(1>nC,"",INDEX(Configuracion!$C$13:$C$20,1)) -> Costo total | C7: =IF(1>nC,"",1) -> 1 | D7: 1 | E7: 5 | F7: 1 | G7: 1 | H7: 1 | I7: 1 | J7: 1 | L7: 3 | M7: Uno importa algo mas
B8: =IF(2>nC,"",INDEX(Configuracion!$C$13:$C$20,2)) -> Tiempo de entrega | C8: =IF(2>nC,"",IF(D7="","",1/D7)) -> 1 | D8: =IF(2>nC,"",1) -> 1 | E8: 5 | F8: 1 | G8: 3 | H8: 1 | I8: 1 | J8: 1 | L8: 5 | M8: Uno importa bastante mas
B9: =IF(3>nC,"",INDEX(Configuracion!$C$13:$C$20,3)) -> Experiencia de usario | C9: =IF(3>nC,"",IF(E7="","",1/E7)) -> 0.2 | D9: =IF(3>nC,"",IF(E8="","",1/E8)) -> 0.2 | E9: =IF(3>nC,"",1) -> 1 | F9: 0.2 | G9: 1 | H9: 1 | I9: 1 | J9: 1 | L9: 7 | M9: Uno importa mucho mas
B10: =IF(4>nC,"",INDEX(Configuracion!$C$13:$C$20,4)) -> Funciona sin internet | C10: =IF(4>nC,"",IF(F7="","",1/F7)) -> 1 | D10: =IF(4>nC,"",IF(F8="","",1/F8)) -> 1 | E10: =IF(4>nC,"",IF(F9="","",1/F9)) -> 5 | F10: =IF(4>nC,"",1) -> 1 | G10: 5 | H10: 1 | I10: 1 | J10: 1 | L10: 9 | M10: Uno importa muchisimo mas
B11: =IF(5>nC,"",INDEX(Configuracion!$C$13:$C$20,5)) -> Seguridad | C11: =IF(5>nC,"",IF(G7="","",1/G7)) -> 1 | D11: =IF(5>nC,"",IF(G8="","",1/G8)) -> 0.33333333 | E11: =IF(5>nC,"",IF(G9="","",1/G9)) -> 1 | F11: =IF(5>nC,"",IF(G10="","",1/G10)) -> 0.2 | G11: =IF(5>nC,"",1) -> 1 | H11: 1 | I11: 1 | J11: 1 | L11: 1/3 | M11: Al reves: escribe =1/3
B12: =IF(6>nC,"",INDEX(Configuracion!$C$13:$C$20,6)) | C12: =IF(6>nC,"",IF(H7="","",1/H7)) | D12: =IF(6>nC,"",IF(H8="","",1/H8)) | E12: =IF(6>nC,"",IF(H9="","",1/H9)) | F12: =IF(6>nC,"",IF(H10="","",1/H10)) | G12: =IF(6>nC,"",IF(H11="","",1/H11)) | H12: =IF(6>nC,"",1) | I12: 1 | J12: 1 | L12: 1/5 | M12: Al reves, con mas fuerza: =1/5
B13: =IF(7>nC,"",INDEX(Configuracion!$C$13:$C$20,7)) | C13: =IF(7>nC,"",IF(I7="","",1/I7)) | D13: =IF(7>nC,"",IF(I8="","",1/I8)) | E13: =IF(7>nC,"",IF(I9="","",1/I9)) | F13: =IF(7>nC,"",IF(I10="","",1/I10)) | G13: =IF(7>nC,"",IF(I11="","",1/I11)) | H13: =IF(7>nC,"",IF(I12="","",1/I12)) | I13: =IF(7>nC,"",1) | J13: 1 | L13: 1/9 | M13: Al reves, al maximo: =1/9
B14: =IF(8>nC,"",INDEX(Configuracion!$C$13:$C$20,8)) | C14: =IF(8>nC,"",IF(J7="","",1/J7)) | D14: =IF(8>nC,"",IF(J8="","",1/J8)) | E14: =IF(8>nC,"",IF(J9="","",1/J9)) | F14: =IF(8>nC,"",IF(J10="","",1/J10)) | G14: =IF(8>nC,"",IF(J11="","",1/J11)) | H14: =IF(8>nC,"",IF(J12="","",1/J12)) | I14: =IF(8>nC,"",IF(J13="","",1/J13)) | J14: =IF(8>nC,"",1)
L15: Recuerda: escribe los inversos como formula (=1/3), nunca 1/3 solo, porque Excel lo lee como fecha.
B16: PASO 2 · Suma de cada columna
B17: Suma de la columna | C17: =IF(1>nC,"",SUM(INDEX(C$7:C$14,1):INDEX(C$7:C$14,nC))) -> 4.2 | D17: =IF(2>nC,"",SUM(INDEX(D$7:D$14,1):INDEX(D$7:D$14,nC))) -> 3.5333333 | E17: =IF(3>nC,"",SUM(INDEX(E$7:E$14,1):INDEX(E$7:E$14,nC))) -> 17 | F17: =IF(4>nC,"",SUM(INDEX(F$7:F$14,1):INDEX(F$7:F$14,nC))) -> 3.4 | G17: =IF(5>nC,"",SUM(INDEX(G$7:G$14,1):INDEX(G$7:G$14,nC))) -> 11 | H17: =IF(6>nC,"",SUM(INDEX(H$7:H$14,1):INDEX(H$7:H$14,nC))) | I17: =IF(7>nC,"",SUM(INDEX(I$7:I$14,1):INDEX(I$7:I$14,nC))) | J17: =IF(8>nC,"",SUM(INDEX(J$7:J$14,1):INDEX(J$7:J$14,nC)))
B19: PASO 3 · Matriz normalizada (cada celda dividida por la suma de SU columna)
B20: FILA \ COLUMNA | C20: =IF(1>nC,"",INDEX(Configuracion!$C$13:$C$20,1)) -> Costo total | D20: =IF(2>nC,"",INDEX(Configuracion!$C$13:$C$20,2)) -> Tiempo de entrega | E20: =IF(3>nC,"",INDEX(Configuracion!$C$13:$C$20,3)) -> Experiencia de usario | F20: =IF(4>nC,"",INDEX(Configuracion!$C$13:$C$20,4)) -> Funciona sin internet | G20: =IF(5>nC,"",INDEX(Configuracion!$C$13:$C$20,5)) -> Seguridad | H20: =IF(6>nC,"",INDEX(Configuracion!$C$13:$C$20,6)) | I20: =IF(7>nC,"",INDEX(Configuracion!$C$13:$C$20,7)) | J20: =IF(8>nC,"",INDEX(Configuracion!$C$13:$C$20,8))
B21: =IF(1>nC,"",INDEX(Configuracion!$C$13:$C$20,1)) -> Costo total | C21: =IF(OR(1>nC,1>nC),"",C7/C$17) -> 0.23809524 | D21: =IF(OR(1>nC,2>nC),"",D7/D$17) -> 0.28301887 | E21: =IF(OR(1>nC,3>nC),"",E7/E$17) -> 0.29411765 | F21: =IF(OR(1>nC,4>nC),"",F7/F$17) -> 0.29411765 | G21: =IF(OR(1>nC,5>nC),"",G7/G$17) -> 0.090909091 | H21: =IF(OR(1>nC,6>nC),"",H7/H$17) | I21: =IF(OR(1>nC,7>nC),"",I7/I$17) | J21: =IF(OR(1>nC,8>nC),"",J7/J$17)
B22: =IF(2>nC,"",INDEX(Configuracion!$C$13:$C$20,2)) -> Tiempo de entrega | C22: =IF(OR(2>nC,1>nC),"",C8/C$17) -> 0.23809524 | D22: =IF(OR(2>nC,2>nC),"",D8/D$17) -> 0.28301887 | E22: =IF(OR(2>nC,3>nC),"",E8/E$17) -> 0.29411765 | F22: =IF(OR(2>nC,4>nC),"",F8/F$17) -> 0.29411765 | G22: =IF(OR(2>nC,5>nC),"",G8/G$17) -> 0.27272727 | H22: =IF(OR(2>nC,6>nC),"",H8/H$17) | I22: =IF(OR(2>nC,7>nC),"",I8/I$17) | J22: =IF(OR(2>nC,8>nC),"",J8/J$17)
B23: =IF(3>nC,"",INDEX(Configuracion!$C$13:$C$20,3)) -> Experiencia de usario | C23: =IF(OR(3>nC,1>nC),"",C9/C$17) -> 0.047619048 | D23: =IF(OR(3>nC,2>nC),"",D9/D$17) -> 0.056603774 | E23: =IF(OR(3>nC,3>nC),"",E9/E$17) -> 0.058823529 | F23: =IF(OR(3>nC,4>nC),"",F9/F$17) -> 0.058823529 | G23: =IF(OR(3>nC,5>nC),"",G9/G$17) -> 0.090909091 | H23: =IF(OR(3>nC,6>nC),"",H9/H$17) | I23: =IF(OR(3>nC,7>nC),"",I9/I$17) | J23: =IF(OR(3>nC,8>nC),"",J9/J$17)
B24: =IF(4>nC,"",INDEX(Configuracion!$C$13:$C$20,4)) -> Funciona sin internet | C24: =IF(OR(4>nC,1>nC),"",C10/C$17) -> 0.23809524 | D24: =IF(OR(4>nC,2>nC),"",D10/D$17) -> 0.28301887 | E24: =IF(OR(4>nC,3>nC),"",E10/E$17) -> 0.29411765 | F24: =IF(OR(4>nC,4>nC),"",F10/F$17) -> 0.29411765 | G24: =IF(OR(4>nC,5>nC),"",G10/G$17) -> 0.45454545 | H24: =IF(OR(4>nC,6>nC),"",H10/H$17) | I24: =IF(OR(4>nC,7>nC),"",I10/I$17) | J24: =IF(OR(4>nC,8>nC),"",J10/J$17)
B25: =IF(5>nC,"",INDEX(Configuracion!$C$13:$C$20,5)) -> Seguridad | C25: =IF(OR(5>nC,1>nC),"",C11/C$17) -> 0.23809524 | D25: =IF(OR(5>nC,2>nC),"",D11/D$17) -> 0.094339623 | E25: =IF(OR(5>nC,3>nC),"",E11/E$17) -> 0.058823529 | F25: =IF(OR(5>nC,4>nC),"",F11/F$17) -> 0.058823529 | G25: =IF(OR(5>nC,5>nC),"",G11/G$17) -> 0.090909091 | H25: =IF(OR(5>nC,6>nC),"",H11/H$17) | I25: =IF(OR(5>nC,7>nC),"",I11/I$17) | J25: =IF(OR(5>nC,8>nC),"",J11/J$17)
B26: =IF(6>nC,"",INDEX(Configuracion!$C$13:$C$20,6)) | C26: =IF(OR(6>nC,1>nC),"",C12/C$17) | D26: =IF(OR(6>nC,2>nC),"",D12/D$17) | E26: =IF(OR(6>nC,3>nC),"",E12/E$17) | F26: =IF(OR(6>nC,4>nC),"",F12/F$17) | G26: =IF(OR(6>nC,5>nC),"",G12/G$17) | H26: =IF(OR(6>nC,6>nC),"",H12/H$17) | I26: =IF(OR(6>nC,7>nC),"",I12/I$17) | J26: =IF(OR(6>nC,8>nC),"",J12/J$17)
B27: =IF(7>nC,"",INDEX(Configuracion!$C$13:$C$20,7)) | C27: =IF(OR(7>nC,1>nC),"",C13/C$17) | D27: =IF(OR(7>nC,2>nC),"",D13/D$17) | E27: =IF(OR(7>nC,3>nC),"",E13/E$17) | F27: =IF(OR(7>nC,4>nC),"",F13/F$17) | G27: =IF(OR(7>nC,5>nC),"",G13/G$17) | H27: =IF(OR(7>nC,6>nC),"",H13/H$17) | I27: =IF(OR(7>nC,7>nC),"",I13/I$17) | J27: =IF(OR(7>nC,8>nC),"",J13/J$17)
B28: =IF(8>nC,"",INDEX(Configuracion!$C$13:$C$20,8)) | C28: =IF(OR(8>nC,1>nC),"",C14/C$17) | D28: =IF(OR(8>nC,2>nC),"",D14/D$17) | E28: =IF(OR(8>nC,3>nC),"",E14/E$17) | F28: =IF(OR(8>nC,4>nC),"",F14/F$17) | G28: =IF(OR(8>nC,5>nC),"",G14/G$17) | H28: =IF(OR(8>nC,6>nC),"",H14/H$17) | I28: =IF(OR(8>nC,7>nC),"",I14/I$17) | J28: =IF(OR(8>nC,8>nC),"",J14/J$17)
B30: PASO 4 · Vector de prioridad w (promedio de cada fila de la matriz normalizada)
B31: Elemento | C31: Peso w | D31: Peso % | E31: Que significa
B32: =IF(1>nC,"",INDEX(Configuracion!$C$13:$C$20,1)) -> Costo total | C32: =IF(1>nC,"",AVERAGE(INDEX($C21:$J21,1):INDEX($C21:$J21,nC))) -> 0.2400517 | D32: =IF(1>nC,"",C32) -> 0.2400517 | E32: =IF(1>nC,"","De cada 100 puntos de importancia, este se lleva "&TEXT(C32*100,"0,0")&".") -> De cada 100 puntos de importancia, este se lleva 24.
B33: =IF(2>nC,"",INDEX(Configuracion!$C$13:$C$20,2)) -> Tiempo de entrega | C33: =IF(2>nC,"",AVERAGE(INDEX($C22:$J22,1):INDEX($C22:$J22,nC))) -> 0.27641533 | D33: =IF(2>nC,"",C33) -> 0.27641533 | E33: =IF(2>nC,"","De cada 100 puntos de importancia, este se lleva "&TEXT(C33*100,"0,0")&".") -> De cada 100 puntos de importancia, este se lleva 28.
B34: =IF(3>nC,"",INDEX(Configuracion!$C$13:$C$20,3)) -> Experiencia de usario | C34: =IF(3>nC,"",AVERAGE(INDEX($C23:$J23,1):INDEX($C23:$J23,nC))) -> 0.062555794 | D34: =IF(3>nC,"",C34) -> 0.062555794 | E34: =IF(3>nC,"","De cada 100 puntos de importancia, este se lleva "&TEXT(C34*100,"0,0")&".") -> De cada 100 puntos de importancia, este se lleva 06.
B35: =IF(4>nC,"",INDEX(Configuracion!$C$13:$C$20,4)) -> Funciona sin internet | C35: =IF(4>nC,"",AVERAGE(INDEX($C24:$J24,1):INDEX($C24:$J24,nC))) -> 0.31277897 | D35: =IF(4>nC,"",C35) -> 0.31277897 | E35: =IF(4>nC,"","De cada 100 puntos de importancia, este se lleva "&TEXT(C35*100,"0,0")&".") -> De cada 100 puntos de importancia, este se lleva 31.
B36: =IF(5>nC,"",INDEX(Configuracion!$C$13:$C$20,5)) -> Seguridad | C36: =IF(5>nC,"",AVERAGE(INDEX($C25:$J25,1):INDEX($C25:$J25,nC))) -> 0.1081982 | D36: =IF(5>nC,"",C36) -> 0.1081982 | E36: =IF(5>nC,"","De cada 100 puntos de importancia, este se lleva "&TEXT(C36*100,"0,0")&".") -> De cada 100 puntos de importancia, este se lleva 11.
B37: =IF(6>nC,"",INDEX(Configuracion!$C$13:$C$20,6)) | C37: =IF(6>nC,"",AVERAGE(INDEX($C26:$J26,1):INDEX($C26:$J26,nC))) | D37: =IF(6>nC,"",C37) | E37: =IF(6>nC,"","De cada 100 puntos de importancia, este se lleva "&TEXT(C37*100,"0,0")&".")
B38: =IF(7>nC,"",INDEX(Configuracion!$C$13:$C$20,7)) | C38: =IF(7>nC,"",AVERAGE(INDEX($C27:$J27,1):INDEX($C27:$J27,nC))) | D38: =IF(7>nC,"",C38) | E38: =IF(7>nC,"","De cada 100 puntos de importancia, este se lleva "&TEXT(C38*100,"0,0")&".")
B39: =IF(8>nC,"",INDEX(Configuracion!$C$13:$C$20,8)) | C39: =IF(8>nC,"",AVERAGE(INDEX($C28:$J28,1):INDEX($C28:$J28,nC))) | D39: =IF(8>nC,"",C39) | E39: =IF(8>nC,"","De cada 100 puntos de importancia, este se lleva "&TEXT(C39*100,"0,0")&".")
B40: Suma (debe dar 1) | C40: =SUM(INDEX($C$32:$C$39,1):INDEX($C$32:$C$39,nC)) -> 1
B42: w en horizontal (auxiliar) | C42: =IF(1>nC,"",$C$32) -> 0.2400517 | D42: =IF(2>nC,"",$C$33) -> 0.27641533 | E42: =IF(3>nC,"",$C$34) -> 0.062555794 | F42: =IF(4>nC,"",$C$35) -> 0.31277897 | G42: =IF(5>nC,"",$C$36) -> 0.1081982 | H42: =IF(6>nC,"",$C$37) | I42: =IF(7>nC,"",$C$38) | J42: =IF(8>nC,"",$C$39)
B44: PASO 5 · Comprobacion de consistencia
B45: Elemento | C45: Suma ponderada (A x w) | D45: Peso w | E45: Razon = (A x w) / w
B46: =IF(1>nC,"",INDEX(Configuracion!$C$13:$C$20,1)) -> Costo total | C46: =IF(1>nC,"",SUMPRODUCT(INDEX($C7:$J7,1):INDEX($C7:$J7,nC),INDEX($C$42:$J$42,1):INDEX($C$42:$J$42,nC))) -> 1.2502232 | D46: =IF(1>nC,"",$C$32) -> 0.2400517 | E46: =IF(1>nC,"",C46/D46) -> 5.2081414
...

Sheet C1
B2: Comparacion de las ALTERNATIVAS · criterio 1
B3: Compara las alternativas de a dos MIRANDO SOLO este criterio. Olvida los demas criterios por un momento.
B4: =IF(1>nC,"ESTA HOJA NO SE USA (solo definiste "&nC&" criterios)","Criterio 1: "&INDEX(Configuracion!$C$13:$C$20,1)) -> Criterio 1: Costo total
B6: PASO 1 · Matriz de comparacion por pares (llena SOLO las celdas amarillas) | L6: ESCALA | M6: Cuando usarla
B7: FILA \ COLUMNA | C7: =IF(1>nA,"",INDEX(Configuracion!$E$13:$E$20,1)) -> Nativas | D7: =IF(2>nA,"",INDEX(Configuracion!$E$13:$E$20,2)) -> Multiplataforma | E7: =IF(3>nA,"",INDEX(Configuracion!$E$13:$E$20,3)) -> Aplicación web | F7: =IF(4>nA,"",INDEX(Configuracion!$E$13:$E$20,4)) | G7: =IF(5>nA,"",INDEX(Configuracion!$E$13:$E$20,5)) | H7: =IF(6>nA,"",INDEX(Configuracion!$E$13:$E$20,6)) | I7: =IF(7>nA,"",INDEX(Configuracion!$E$13:$E$20,7)) | J7: =IF(8>nA,"",INDEX(Configuracion!$E$13:$E$20,8)) | L7: 1 | M7: Los dos importan igual
B8: =IF(1>nA,"",INDEX(Configuracion!$E$13:$E$20,1)) -> Nativas | C8: =IF(1>nA,"",1) -> 1 | D8: 9 | E8: 3 | F8: 1 | G8: 1 | H8: 1 | I8: 1 | J8: 1 | L8: 3 | M8: Uno importa algo mas
B9: =IF(2>nA,"",INDEX(Configuracion!$E$13:$E$20,2)) -> Multiplataforma | C9: =IF(2>nA,"",IF(D8="","",1/D8)) -> 0.11111111 | D9: =IF(2>nA,"",1) -> 1 | E9: 3 | F9: 1 | G9: 1 | H9: 1 | I9: 1 | J9: 1 | L9: 5 | M9: Uno importa bastante mas
B10: =IF(3>nA,"",INDEX(Configuracion!$E$13:$E$20,3)) -> Aplicación web | C10: =IF(3>nA,"",IF(E8="","",1/E8)) -> 0.33333333 | D10: =IF(3>nA,"",IF(E9="","",1/E9)) -> 0.33333333 | E10: =IF(3>nA,"",1) -> 1 | F10: 1 | G10: 1 | H10: 1 | I10: 1 | J10: 1 | L10: 7 | M10: Uno importa mucho mas
B11: =IF(4>nA,"",INDEX(Configuracion!$E$13:$E$20,4)) | C11: =IF(4>nA,"",IF(F8="","",1/F8)) | D11: =IF(4>nA,"",IF(F9="","",1/F9)) | E11: =IF(4>nA,"",IF(F10="","",1/F10)) | F11: =IF(4>nA,"",1) | G11: 1 | H11: 1 | I11: 1 | J11: 1 | L11: 9 | M11: Uno importa muchisimo mas
B12: =IF(5>nA,"",INDEX(Configuracion!$E$13:$E$20,5)) | C12: =IF(5>nA,"",IF(G8="","",1/G8)) | D12: =IF(5>nA,"",IF(G9="","",1/G9)) | E12: =IF(5>nA,"",IF(G10="","",1/G10)) | F12: =IF(5>nA,"",IF(G11="","",1/G11)) | G12: =IF(5>nA,"",1) | H12: 1 | I12: 1 | J12: 1 | L12: 1/3 | M12: Al reves: escribe =1/3
B13: =IF(6>nA,"",INDEX(Configuracion!$E$13:$E$20,6)) | C13: =IF(6>nA,"",IF(H8="","",1/H8)) | D13: =IF(6>nA,"",IF(H9="","",1/H9)) | E13: =IF(6>nA,"",IF(H10="","",1/H10)) | F13: =IF(6>nA,"",IF(H11="","",1/H11)) | G13: =IF(6>nA,"",IF(H12="","",1/H12)) | H13: =IF(6>nA,"",1) | I13: 1 | J13: 1 | L13: 1/5 | M13: Al reves, con mas fuerza: =1/5
B14: =IF(7>nA,"",INDEX(Configuracion!$E$13:$E$20,7)) | C14: =IF(7>nA,"",IF(I8="","",1/I8)) | D14: =IF(7>nA,"",IF(I9="","",1/I9)) | E14: =IF(7>nA,"",IF(I10="","",1/I10)) | F14: =IF(7>nA,"",IF(I11="","",1/I11)) | G14: =IF(7>nA,"",IF(I12="","",1/I12)) | H14: =IF(7>nA,"",IF(I13="","",1/I13)) | I14: =IF(7>nA,"",1) | J14: 1 | L14: 1/9 | M14: Al reves, al maximo: =1/9
B15: =IF(8>nA,"",INDEX(Configuracion!$E$13:$E$20,8)) | C15: =IF(8>nA,"",IF(J8="","",1/J8)) | D15: =IF(8>nA,"",IF(J9="","",1/J9)) | E15: =IF(8>nA,"",IF(J10="","",1/J10)) | F15: =IF(8>nA,"",IF(J11="","",1/J11)) | G15: =IF(8>nA,"",IF(J12="","",1/J12)) | H15: =IF(8>nA,"",IF(J13="","",1/J13)) | I15: =IF(8>nA,"",IF(J14="","",1/J14)) | J15: =IF(8>nA,"",1)
L16: Recuerda: escribe los inversos como formula (=1/3), nunca 1/3 solo, porque Excel lo lee como fecha.
B17: PASO 2 · Suma de cada columna
B18: Suma de la columna | C18: =IF(1>nA,"",SUM(INDEX(C$8:C$15,1):INDEX(C$8:C$15,nA))) -> 1.4444444 | D18: =IF(2>nA,"",SUM(INDEX(D$8:D$15,1):INDEX(D$8:D$15,nA))) -> 10.333333 | E18: =IF(3>nA,"",SUM(INDEX(E$8:E$15,1):INDEX(E$8:E$15,nA))) -> 7 | F18: =IF(4>nA,"",SUM(INDEX(F$8:F$15,1):INDEX(F$8:F$15,nA))) | G18: =IF(5>nA,"",SUM(INDEX(G$8:G$15,1):INDEX(G$8:G$15,nA))) | H18: =IF(6>nA,"",SUM(INDEX(H$8:H$15,1):INDEX(H$8:H$15,nA))) | I18: =IF(7>nA,"",SUM(INDEX(I$8:I$15,1):INDEX(I$8:I$15,nA))) | J18: =IF(8>nA,"",SUM(INDEX(J$8:J$15,1):INDEX(J$8:J$15,nA)))
B20: PASO 3 · Matriz normalizada (cada celda dividida por la suma de SU columna)
B21: FILA \ COLUMNA | C21: =IF(1>nA,"",INDEX(Configuracion!$E$13:$E$20,1)) -> Nativas | D21: =IF(2>nA,"",INDEX(Configuracion!$E$13:$E$20,2)) -> Multiplataforma | E21: =IF(3>nA,"",INDEX(Configuracion!$E$13:$E$20,3)) -> Aplicación web | F21: =IF(4>nA,"",INDEX(Configuracion!$E$13:$E$20,4)) | G21: =IF(5>nA,"",INDEX(Configuracion!$E$13:$E$20,5)) | H21: =IF(6>nA,"",INDEX(Configuracion!$E$13:$E$20,6)) | I21: =IF(7>nA,"",INDEX(Configuracion!$E$13:$E$20,7)) | J21: =IF(8>nA,"",INDEX(Configuracion!$E$13:$E$20,8))
B22: =IF(1>nA,"",INDEX(Configuracion!$E$13:$E$20,1)) -> Nativas | C22: =IF(OR(1>nA,1>nA),"",C8/C$18) -> 0.69230769 | D22: =IF(OR(1>nA,2>nA),"",D8/D$18) -> 0.87096774 | E22: =IF(OR(1>nA,3>nA),"",E8/E$18) -> 0.42857143 | F22: =IF(OR(1>nA,4>nA),"",F8/F$18) | G22: =IF(OR(1>nA,5>nA),"",G8/G$18) | H22: =IF(OR(1>nA,6>nA),"",H8/H$18) | I22: =IF(OR(1>nA,7>nA),"",I8/I$18) | J22: =IF(OR(1>nA,8>nA),"",J8/J$18)
B23: =IF(2>nA,"",INDEX(Configuracion!$E$13:$E$20,2)) -> Multiplataforma | C23: =IF(OR(2>nA,1>nA),"",C9/C$18) -> 0.076923077 | D23: =IF(OR(2>nA,2>nA),"",D9/D$18) -> 0.096774194 | E23: =IF(OR(2>nA,3>nA),"",E9/E$18) -> 0.42857143 | F23: =IF(OR(2>nA,4>nA),"",F9/F$18) | G23: =IF(OR(2>nA,5>nA),"",G9/G$18) | H23: =IF(OR(2>nA,6>nA),"",H9/H$18) | I23: =IF(OR(2>nA,7>nA),"",I9/I$18) | J23: =IF(OR(2>nA,8>nA),"",J9/J$18)
B24: =IF(3>nA,"",INDEX(Configuracion!$E$13:$E$20,3)) -> Aplicación web | C24: =IF(OR(3>nA,1>nA),"",C10/C$18) -> 0.23076923 | D24: =IF(OR(3>nA,2>nA),"",D10/D$18) -> 0.032258065 | E24: =IF(OR(3>nA,3>nA),"",E10/E$18) -> 0.14285714 | F24: =IF(OR(3>nA,4>nA),"",F10/F$18) | G24: =IF(OR(3>nA,5>nA),"",G10/G$18) | H24: =IF(OR(3>nA,6>nA),"",H10/H$18) | I24: =IF(OR(3>nA,7>nA),"",I10/I$18) | J24: =IF(OR(3>nA,8>nA),"",J10/J$18)
B25: =IF(4>nA,"",INDEX(Configuracion!$E$13:$E$20,4)) | C25: =IF(OR(4>nA,1>nA),"",C11/C$18) | D25: =IF(OR(4>nA,2>nA),"",D11/D$18) | E25: =IF(OR(4>nA,3>nA),"",E11/E$18) | F25: =IF(OR(4>nA,4>nA),"",F11/F$18) | G25: =IF(OR(4>nA,5>nA),"",G11/G$18) | H25: =IF(OR(4>nA,6>nA),"",H11/H$18) | I25: =IF(OR(4>nA,7>nA),"",I11/I$18) | J25: =IF(OR(4>nA,8>nA),"",J11/J$18)
B26: =IF(5>nA,"",INDEX(Configuracion!$E$13:$E$20,5)) | C26: =IF(OR(5>nA,1>nA),"",C12/C$18) | D26: =IF(OR(5>nA,2>nA),"",D12/D$18) | E26: =IF(OR(5>nA,3>nA),"",E12/E$18) | F26: =IF(OR(5>nA,4>nA),"",F12/F$18) | G26: =IF(OR(5>nA,5>nA),"",G12/G$18) | H26: =IF(OR(5>nA,6>nA),"",H12/H$18) | I26: =IF(OR(5>nA,7>nA),"",I12/I$18) | J26: =IF(OR(5>nA,8>nA),"",J12/J$18)
B27: =IF(6>nA,"",INDEX(Configuracion!$E$13:$E$20,6)) | C27: =IF(OR(6>nA,1>nA),"",C13/C$18) | D27: =IF(OR(6>nA,2>nA),"",D13/D$18) | E27: =IF(OR(6>nA,3>nA),"",E13/E$18) | F27: =IF(OR(6>nA,4>nA),"",F13/F$18) | G27: =IF(OR(6>nA,5>nA),"",G13/G$18) | H27: =IF(OR(6>nA,6>nA),"",H13/H$18) | I27: =IF(OR(6>nA,7>nA),"",I13/I$18) | J27: =IF(OR(6>nA,8>nA),"",J13/J$18)
B28: =IF(7>nA,"",INDEX(Configuracion!$E$13:$E$20,7)) | C28: =IF(OR(7>nA,1>nA),"",C14/C$18) | D28: =IF(OR(7>nA,2>nA),"",D14/D$18) | E28: =IF(OR(7>nA,3>nA),"",E14/E$18) | F28: =IF(OR(7>nA,4>nA),"",F14/F$18) | G28: =IF(OR(7>nA,5>nA),"",G14/G$18) | H28: =IF(OR(7>nA,6>nA),"",H14/H$18) | I28: =IF(OR(7>nA,7>nA),"",I14/I$18) | J28: =IF(OR(7>nA,8>nA),"",J14/J$18)
B29: =IF(8>nA,"",INDEX(Configuracion!$E$13:$E$20,8)) | C29: =IF(OR(8>nA,1>nA),"",C15/C$18) | D29: =IF(OR(8>nA,2>nA),"",D15/D$18) | E29: =IF(OR(8>nA,3>nA),"",E15/E$18) | F29: =IF(OR(8>nA,4>nA),"",F15/F$18) | G29: =IF(OR(8>nA,5>nA),"",G15/G$18) | H29: =IF(OR(8>nA,6>nA),"",H15/H$18) | I29: =IF(OR(8>nA,7>nA),"",I15/I$18) | J29: =IF(OR(8>nA,8>nA),"",J15/J$18)
B31: PASO 4 · Vector de prioridad w (promedio de cada fila de la matriz normalizada)
B32: Elemento | C32: Peso w | D32: Peso % | E32: Que significa
B33: =IF(1>nA,"",INDEX(Configuracion!$E$13:$E$20,1)) -> Nativas | C33: =IF(1>nA,"",AVERAGE(INDEX($C22:$J22,1):INDEX($C22:$J22,nA))) -> 0.66394895 | D33: =IF(1>nA,"",C33) -> 0.66394895 | E33: =IF(1>nA,"","De cada 100 puntos de importancia, este se lleva "&TEXT(C33*100,"0,0")&".") -> De cada 100 puntos de importancia, este se lleva 66.
B34: =IF(2>nA,"",INDEX(Configuracion!$E$13:$E$20,2)) -> Multiplataforma | C34: =IF(2>nA,"",AVERAGE(INDEX($C23:$J23,1):INDEX($C23:$J23,nA))) -> 0.20075623 | D34: =IF(2>nA,"",C34) -> 0.20075623 | E34: =IF(2>nA,"","De cada 100 puntos de importancia, este se lleva "&TEXT(C34*100,"0,0")&".") -> De cada 100 puntos de importancia, este se lleva 20.
B35: =IF(3>nA,"",INDEX(Configuracion!$E$13:$E$20,3)) -> Aplicación web | C35: =IF(3>nA,"",AVERAGE(INDEX($C24:$J24,1):INDEX($C24:$J24,nA))) -> 0.13529481 | D35: =IF(3>nA,"",C35) -> 0.13529481 | E35: =IF(3>nA,"","De cada 100 puntos de importancia, este se lleva "&TEXT(C35*100,"0,0")&".") -> De cada 100 puntos de importancia, este se lleva 14.
B36: =IF(4>nA,"",INDEX(Configuracion!$E$13:$E$20,4)) | C36: =IF(4>nA,"",AVERAGE(INDEX($C25:$J25,1):INDEX($C25:$J25,nA))) | D36: =IF(4>nA,"",C36) | E36: =IF(4>nA,"","De cada 100 puntos de importancia, este se lleva "&TEXT(C36*100,"0,0")&".")
B37: =IF(5>nA,"",INDEX(Configuracion!$E$13:$E$20,5)) | C37: =IF(5>nA,"",AVERAGE(INDEX($C26:$J26,1):INDEX($C26:$J26,nA))) | D37: =IF(5>nA,"",C37) | E37: =IF(5>nA,"","De cada 100 puntos de importancia, este se lleva "&TEXT(C37*100,"0,0")&".")
B38: =IF(6>nA,"",INDEX(Configuracion!$E$13:$E$20,6)) | C38: =IF(6>nA,"",AVERAGE(INDEX($C27:$J27,1):INDEX($C27:$J27,nA))) | D38: =IF(6>nA,"",C38) | E38: =IF(6>nA,"","De cada 100 puntos de importancia, este se lleva "&TEXT(C38*100,"0,0")&".")
B39: =IF(7>nA,"",INDEX(Configuracion!$E$13:$E$20,7)) | C39: =IF(7>nA,"",AVERAGE(INDEX($C28:$J28,1):INDEX($C28:$J28,nA))) | D39: =IF(7>nA,"",C39) | E39: =IF(7>nA,"","De cada 100 puntos de importancia, este se lleva "&TEXT(C39*100,"0,0")&".")
B40: =IF(8>nA,"",INDEX(Configuracion!$E$13:$E$20,8)) | C40: =IF(8>nA,"",AVERAGE(INDEX($C29:$J29,1):INDEX($C29:$J29,nA))) | D40: =IF(8>nA,"",C40) | E40: =IF(8>nA,"","De cada 100 puntos de importancia, este se lleva "&TEXT(C40*100,"0,0")&".")
B41: Suma (debe dar 1) | C41: =SUM(INDEX($C$33:$C$40,1):INDEX($C$33:$C$40,nA)) -> 1
B43: w en horizontal (auxiliar) | C43: =IF(1>nA,"",$C$33) -> 0.66394895 | D43: =IF(2>nA,"",$C$34) -> 0.20075623 | E43: =IF(3>nA,"",$C$35) -> 0.13529481 | F43: =IF(4>nA,"",$C$36) | G43: =IF(5>nA,"",$C$37) | H43: =IF(6>nA,"",$C$38) | I43: =IF(7>nA,"",$C$39) | J43: =IF(8>nA,"",$C$40)
B45: PASO 5 · Comprobacion de consistencia
B46: Elemento | C46: Suma ponderada (A x w) | D46: Peso w | E46: Razon = (A x w) / w
...

Sheet C2
B2: Comparacion de las ALTERNATIVAS · criterio 2
B3: Compara las alternativas de a dos MIRANDO SOLO este criterio. Olvida los demas criterios por un momento.
B4: =IF(2>nC,"ESTA HOJA NO SE USA (solo definiste "&nC&" criterios)","Criterio 2: "&INDEX(Configuracion!$C$13:$C$20,2)) -> Criterio 2: Tiempo de entrega
B6: PASO 1 · Matriz de comparacion por pares (llena SOLO las celdas amarillas) | L6: ESCALA | M6: Cuando usarla
B7: FILA \ COLUMNA | C7: =IF(1>nA,"",INDEX(Configuracion!$E$13:$E$20,1)) -> Nativas | D7: =IF(2>nA,"",INDEX(Configuracion!$E$13:$E$20,2)) -> Multiplataforma | E7: =IF(3>nA,"",INDEX(Configuracion!$E$13:$E$20,3)) -> Aplicación web | F7: =IF(4>nA,"",INDEX(Configuracion!$E$13:$E$20,4)) | G7: =IF(5>nA,"",INDEX(Configuracion!$E$13:$E$20,5)) | H7: =IF(6>nA,"",INDEX(Configuracion!$E$13:$E$20,6)) | I7: =IF(7>nA,"",INDEX(Configuracion!$E$13:$E$20,7)) | J7: =IF(8>nA,"",INDEX(Configuracion!$E$13:$E$20,8)) | L7: 1 | M7: Los dos importan igual
B8: =IF(1>nA,"",INDEX(Configuracion!$E$13:$E$20,1)) -> Nativas | C8: =IF(1>nA,"",1) -> 1 | D8: 5 | E8: 2 | F8: 1 | G8: 1 | H8: 1 | I8: 1 | J8: 1 | L8: 3 | M8: Uno importa algo mas
B9: =IF(2>nA,"",INDEX(Configuracion!$E$13:$E$20,2)) -> Multiplataforma | C9: =IF(2>nA,"",IF(D8="","",1/D8)) -> 0.2 | D9: =IF(2>nA,"",1) -> 1 | E9: 0.33333333 | F9: 1 | G9: 1 | H9: 1 | I9: 1 | J9: 1 | L9: 5 | M9: Uno importa bastante mas
B10: =IF(3>nA,"",INDEX(Configuracion!$E$13:$E$20,3)) -> Aplicación web | C10: =IF(3>nA,"",IF(E8="","",1/E8)) -> 0.5 | D10: =IF(3>nA,"",IF(E9="","",1/E9)) -> 3 | E10: =IF(3>nA,"",1) -> 1 | F10: 1 | G10: 1 | H10: 1 | I10: 1 | J10: 1 | L10: 7 | M10: Uno importa mucho mas
B11: =IF(4>nA,"",INDEX(Configuracion!$E$13:$E$20,4)) | C11: =IF(4>nA,"",IF(F8="","",1/F8)) | D11: =IF(4>nA,"",IF(F9="","",1/F9)) | E11: =IF(4>nA,"",IF(F10="","",1/F10)) | F11: =IF(4>nA,"",1) | G11: 1 | H11: 1 | I11: 1 | J11: 1 | L11: 9 | M11: Uno importa muchisimo mas
B12: =IF(5>nA,"",INDEX(Configuracion!$E$13:$E$20,5)) | C12: =IF(5>nA,"",IF(G8="","",1/G8)) | D12: =IF(5>nA,"",IF(G9="","",1/G9)) | E12: =IF(5>nA,"",IF(G10="","",1/G10)) | F12: =IF(5>nA,"",IF(G11="","",1/G11)) | G12: =IF(5>nA,"",1) | H12: 1 | I12: 1 | J12: 1 | L12: 1/3 | M12: Al reves: escribe =1/3
B13: =IF(6>nA,"",INDEX(Configuracion!$E$13:$E$20,6)) | C13: =IF(6>nA,"",IF(H8="","",1/H8)) | D13: =IF(6>nA,"",IF(H9="","",1/H9)) | E13: =IF(6>nA,"",IF(H10="","",1/H10)) | F13: =IF(6>nA,"",IF(H11="","",1/H11)) | G13: =IF(6>nA,"",IF(H12="","",1/H12)) | H13: =IF(6>nA,"",1) | I13: 1 | J13: 1 | L13: 1/5 | M13: Al reves, con mas fuerza: =1/5
B14: =IF(7>nA,"",INDEX(Configuracion!$E$13:$E$20,7)) | C14: =IF(7>nA,"",IF(I8="","",1/I8)) | D14: =IF(7>nA,"",IF(I9="","",1/I9)) | E14: =IF(7>nA,"",IF(I10="","",1/I10)) | F14: =IF(7>nA,"",IF(I11="","",1/I11)) | G14: =IF(7>nA,"",IF(I12="","",1/I12)) | H14: =IF(7>nA,"",IF(I13="","",1/I13)) | I14: =IF(7>nA,"",1) | J14: 1 | L14: 1/9 | M14: Al reves, al maximo: =1/9
B15: =IF(8>nA,"",INDEX(Configuracion!$E$13:$E$20,8)) | C15: =IF(8>nA,"",IF(J8="","",1/J8)) | D15: =IF(8>nA,"",IF(J9="","",1/J9)) | E15: =IF(8>nA,"",IF(J10="","",1/J10)) | F15: =IF(8>nA,"",IF(J11="","",1/J11)) | G15: =IF(8>nA,"",IF(J12="","",1/J12)) | H15: =IF(8>nA,"",IF(J13="","",1/J13)) | I15: =IF(8>nA,"",IF(J14="","",1/J14)) | J15: =IF(8>nA,"",1)
L16: Recuerda: escribe los inversos como formula (=1/3), nunca 1/3 solo, porque Excel lo lee como fecha.
B17: PASO 2 · Suma de cada columna
B18: Suma de la columna | C18: =IF(1>nA,"",SUM(INDEX(C$8:C$15,1):INDEX(C$8:C$15,nA))) -> 1.7 | D18: =IF(2>nA,"",SUM(INDEX(D$8:D$15,1):INDEX(D$8:D$15,nA))) -> 9 | E18: =IF(3>nA,"",SUM(INDEX(E$8:E$15,1):INDEX(E$8:E$15,nA))) -> 3.3333333 | F18: =IF(4>nA,"",SUM(INDEX(F$8:F$15,1):INDEX(F$8:F$15,nA))) | G18: =IF(5>nA,"",SUM(INDEX(G$8:G$15,1):INDEX(G$8:G$15,nA))) | H18: =IF(6>nA,"",SUM(INDEX(H$8:H$15,1):INDEX(H$8:H$15,nA))) | I18: =IF(7>nA,"",SUM(INDEX(I$8:I$15,1):INDEX(I$8:I$15,nA))) | J18: =IF(8>nA,"",SUM(INDEX(J$8:J$15,1):INDEX(J$8:J$15,nA)))
B20: PASO 3 · Matriz normalizada (cada celda dividida por la suma de SU columna)
B21: FILA \ COLUMNA | C21: =IF(1>nA,"",INDEX(Configuracion!$E$13:$E$20,1)) -> Nativas | D21: =IF(2>nA,"",INDEX(Configuracion!$E$13:$E$20,2)) -> Multiplataforma | E21: =IF(3>nA,"",INDEX(Configuracion!$E$13:$E$20,3)) -> Aplicación web | F21: =IF(4>nA,"",INDEX(Configuracion!$E$13:$E$20,4)) | G21: =IF(5>nA,"",INDEX(Configuracion!$E$13:$E$20,5)) | H21: =IF(6>nA,"",INDEX(Configuracion!$E$13:$E$20,6)) | I21: =IF(7>nA,"",INDEX(Configuracion!$E$13:$E$20,7)) | J21: =IF(8>nA,"",INDEX(Configuracion!$E$13:$E$20,8))
B22: =IF(1>nA,"",INDEX(Configuracion!$E$13:$E$20,1)) -> Nativas | C22: =IF(OR(1>nA,1>nA),"",C8/C$18) -> 0.58823529 | D22: =IF(OR(1>nA,2>nA),"",D8/D$18) -> 0.55555556 | E22: =IF(OR(1>nA,3>nA),"",E8/E$18) -> 0.6 | F22: =IF(OR(1>nA,4>nA),"",F8/F$18) | G22: =IF(OR(1>nA,5>nA),"",G8/G$18) | H22: =IF(OR(1>nA,6>nA),"",H8/H$18) | I22: =IF(OR(1>nA,7>nA),"",I8/I$18) | J22: =IF(OR(1>nA,8>nA),"",J8/J$18)
B23: =IF(2>nA,"",INDEX(Configuracion!$E$13:$E$20,2)) -> Multiplataforma | C23: =IF(OR(2>nA,1>nA),"",C9/C$18) -> 0.11764706 | D23: =IF(OR(2>nA,2>nA),"",D9/D$18) -> 0.11111111 | E23: =IF(OR(2>nA,3>nA),"",E9/E$18) -> 0.1 | F23: =IF(OR(2>nA,4>nA),"",F9/F$18) | G23: =IF(OR(2>nA,5>nA),"",G9/G$18) | H23: =IF(OR(2>nA,6>nA),"",H9/H$18) | I23: =IF(OR(2>nA,7>nA),"",I9/I$18) | J23: =IF(OR(2>nA,8>nA),"",J9/J$18)
B24: =IF(3>nA,"",INDEX(Configuracion!$E$13:$E$20,3)) -> Aplicación web | C24: =IF(OR(3>nA,1>nA),"",C10/C$18) -> 0.29411765 | D24: =IF(OR(3>nA,2>nA),"",D10/D$18) -> 0.33333333 | E24: =IF(OR(3>nA,3>nA),"",E10/E$18) -> 0.3 | F24: =IF(OR(3>nA,4>nA),"",F10/F$18) | G24: =IF(OR(3>nA,5>nA),"",G10/G$18) | H24: =IF(OR(3>nA,6>nA),"",H10/H$18) | I24: =IF(OR(3>nA,7>nA),"",I10/I$18) | J24: =IF(OR(3>nA,8>nA),"",J10/J$18)
B25: =IF(4>nA,"",INDEX(Configuracion!$E$13:$E$20,4)) | C25: =IF(OR(4>nA,1>nA),"",C11/C$18) | D25: =IF(OR(4>nA,2>nA),"",D11/D$18) | E25: =IF(OR(4>nA,3>nA),"",E11/E$18) | F25: =IF(OR(4>nA,4>nA),"",F11/F$18) | G25: =IF(OR(4>nA,5>nA),"",G11/G$18) | H25: =IF(OR(4>nA,6>nA),"",H11/H$18) | I25: =IF(OR(4>nA,7>nA),"",I11/I$18) | J25: =IF(OR(4>nA,8>nA),"",J11/J$18)
B26: =IF(5>nA,"",INDEX(Configuracion!$E$13:$E$20,5)) | C26: =IF(OR(5>nA,1>nA),"",C12/C$18) | D26: =IF(OR(5>nA,2>nA),"",D12/D$18) | E26: =IF(OR(5>nA,3>nA),"",E12/E$18) | F26: =IF(OR(5>nA,4>nA),"",F12/F$18) | G26: =IF(OR(5>nA,5>nA),"",G12/G$18) | H26: =IF(OR(5>nA,6>nA),"",H12/H$18) | I26: =IF(OR(5>nA,7>nA),"",I12/I$18) | J26: =IF(OR(5>nA,8>nA),"",J12/J$18)
B27: =IF(6>nA,"",INDEX(Configuracion!$E$13:$E$20,6)) | C27: =IF(OR(6>nA,1>nA),"",C13/C$18) | D27: =IF(OR(6>nA,2>nA),"",D13/D$18) | E27: =IF(OR(6>nA,3>nA),"",E13/E$18) | F27: =IF(OR(6>nA,4>nA),"",F13/F$18) | G27: =IF(OR(6>nA,5>nA),"",G13/G$18) | H27: =IF(OR(6>nA,6>nA),"",H13/H$18) | I27: =IF(OR(6>nA,7>nA),"",I13/I$18) | J27: =IF(OR(6>nA,8>nA),"",J13/J$18)
B28: =IF(7>nA,"",INDEX(Configuracion!$E$13:$E$20,7)) | C28: =IF(OR(7>nA,1>nA),"",C14/C$18) | D28: =IF(OR(7>nA,2>nA),"",D14/D$18) | E28: =IF(OR(7>nA,3>nA),"",E14/E$18) | F28: =IF(OR(7>nA,4>nA),"",F14/F$18) | G28: =IF(OR(7>nA,5>nA),"",G14/G$18) | H28: =IF(OR(7>nA,6>nA),"",H14/H$18) | I28: =IF(OR(7>nA,7>nA),"",I14/I$18) | J28: =IF(OR(7>nA,8>nA),"",J14/J$18)
B29: =IF(8>nA,"",INDEX(Configuracion!$E$13:$E$20,8)) | C29: =IF(OR(8>nA,1>nA),"",C15/C$18) | D29: =IF(OR(8>nA,2>nA),"",D15/D$18) | E29: =IF(OR(8>nA,3>nA),"",E15/E$18) | F29: =IF(OR(8>nA,4>nA),"",F15/F$18) | G29: =IF(OR(8>nA,5>nA),"",G15/G$18) | H29: =IF(OR(8>nA,6>nA),"",H15/H$18) | I29: =IF(OR(8>nA,7>nA),"",I15/I$18) | J29: =IF(OR(8>nA,8>nA),"",J15/J$18)
B31: PASO 4 · Vector de prioridad w (promedio de cada fila de la matriz normalizada)
B32: Elemento | C32: Peso w | D32: Peso % | E32: Que significa
B33: =IF(1>nA,"",INDEX(Configuracion!$E$13:$E$20,1)) -> Nativas | C33: =IF(1>nA,"",AVERAGE(INDEX($C22:$J22,1):INDEX($C22:$J22,nA))) -> 0.58126362 | D33: =IF(1>nA,"",C33) -> 0.58126362 | E33: =IF(1>nA,"","De cada 100 puntos de importancia, este se lleva "&TEXT(C33*100,"0,0")&".") -> De cada 100 puntos de importancia, este se lleva 58.
B34: =IF(2>nA,"",INDEX(Configuracion!$E$13:$E$20,2)) -> Multiplataforma | C34: =IF(2>nA,"",AVERAGE(INDEX($C23:$J23,1):INDEX($C23:$J23,nA))) -> 0.10958606 | D34: =IF(2>nA,"",C34) -> 0.10958606 | E34: =IF(2>nA,"","De cada 100 puntos de importancia, este se lleva "&TEXT(C34*100,"0,0")&".") -> De cada 100 puntos de importancia, este se lleva 11.
B35: =IF(3>nA,"",INDEX(Configuracion!$E$13:$E$20,3)) -> Aplicación web | C35: =IF(3>nA,"",AVERAGE(INDEX($C24:$J24,1):INDEX($C24:$J24,nA))) -> 0.30915033 | D35: =IF(3>nA,"",C35) -> 0.30915033 | E35: =IF(3>nA,"","De cada 100 puntos de importancia, este se lleva "&TEXT(C35*100,"0,0")&".") -> De cada 100 puntos de importancia, este se lleva 31.
B36: =IF(4>nA,"",INDEX(Configuracion!$E$13:$E$20,4)) | C36: =IF(4>nA,"",AVERAGE(INDEX($C25:$J25,1):INDEX($C25:$J25,nA))) | D36: =IF(4>nA,"",C36) | E36: =IF(4>nA,"","De cada 100 puntos de importancia, este se lleva "&TEXT(C36*100,"0,0")&".")
B37: =IF(5>nA,"",INDEX(Configuracion!$E$13:$E$20,5)) | C37: =IF(5>nA,"",AVERAGE(INDEX($C26:$J26,1):INDEX($C26:$J26,nA))) | D37: =IF(5>nA,"",C37) | E37: =IF(5>nA,"","De cada 100 puntos de importancia, este se lleva "&TEXT(C37*100,"0,0")&".")
B38: =IF(6>nA,"",INDEX(Configuracion!$E$13:$E$20,6)) | C38: =IF(6>nA,"",AVERAGE(INDEX($C27:$J27,1):INDEX($C27:$J27,nA))) | D38: =IF(6>nA,"",C38) | E38: =IF(6>nA,"","De cada 100 puntos de importancia, este se lleva "&TEXT(C38*100,"0,0")&".")
B39: =IF(7>nA,"",INDEX(Configuracion!$E$13:$E$20,7)) | C39: =IF(7>nA,"",AVERAGE(INDEX($C28:$J28,1):INDEX($C28:$J28,nA))) | D39: =IF(7>nA,"",C39) | E39: =IF(7>nA,"","De cada 100 puntos de importancia, este se lleva "&TEXT(C39*100,"0,0")&".")
B40: =IF(8>nA,"",INDEX(Configuracion!$E$13:$E$20,8)) | C40: =IF(8>nA,"",AVERAGE(INDEX($C29:$J29,1):INDEX($C29:$J29,nA))) | D40: =IF(8>nA,"",C40) | E40: =IF(8>nA,"","De cada 100 puntos de importancia, este se lleva "&TEXT(C40*100,"0,0")&".")
B41: Suma (debe dar 1) | C41: =SUM(INDEX($C$33:$C$40,1):INDEX($C$33:$C$40,nA)) -> 1
B43: w en horizontal (auxiliar) | C43: =IF(1>nA,"",$C$33) -> 0.58126362 | D43: =IF(2>nA,"",$C$34) -> 0.10958606 | E43: =IF(3>nA,"",$C$35) -> 0.30915033 | F43: =IF(4>nA,"",$C$36) | G43: =IF(5>nA,"",$C$37) | H43: =IF(6>nA,"",$C$38) | I43: =IF(7>nA,"",$C$39) | J43: =IF(8>nA,"",$C$40)
B45: PASO 5 · Comprobacion de consistencia
B46: Elemento | C46: Suma ponderada (A x w) | D46: Peso w | E46: Razon = (A x w) / w
...

Sheet C3
B2: Comparacion de las ALTERNATIVAS · criterio 3
B3: Compara las alternativas de a dos MIRANDO SOLO este criterio. Olvida los demas criterios por un momento.
B4: =IF(3>nC,"ESTA HOJA NO SE USA (solo definiste "&nC&" criterios)","Criterio 3: "&INDEX(Configuracion!$C$13:$C$20,3)) -> Criterio 3: Experiencia de usario
B6: PASO 1 · Matriz de comparacion por pares (llena SOLO las celdas amarillas) | L6: ESCALA | M6: Cuando usarla
B7: FILA \ COLUMNA | C7: =IF(1>nA,"",INDEX(Configuracion!$E$13:$E$20,1)) -> Nativas | D7: =IF(2>nA,"",INDEX(Configuracion!$E$13:$E$20,2)) -> Multiplataforma | E7: =IF(3>nA,"",INDEX(Configuracion!$E$13:$E$20,3)) -> Aplicación web | F7: =IF(4>nA,"",INDEX(Configuracion!$E$13:$E$20,4)) | G7: =IF(5>nA,"",INDEX(Configuracion!$E$13:$E$20,5)) | H7: =IF(6>nA,"",INDEX(Configuracion!$E$13:$E$20,6)) | I7: =IF(7>nA,"",INDEX(Configuracion!$E$13:$E$20,7)) | J7: =IF(8>nA,"",INDEX(Configuracion!$E$13:$E$20,8)) | L7: 1 | M7: Los dos importan igual
B8: =IF(1>nA,"",INDEX(Configuracion!$E$13:$E$20,1)) -> Nativas | C8: =IF(1>nA,"",1) -> 1 | D8: 0.5 | E8: 0.33333333 | F8: 1 | G8: 1 | H8: 1 | I8: 1 | J8: 1 | L8: 3 | M8: Uno importa algo mas
B9: =IF(2>nA,"",INDEX(Configuracion!$E$13:$E$20,2)) -> Multiplataforma | C9: =IF(2>nA,"",IF(D8="","",1/D8)) -> 2 | D9: =IF(2>nA,"",1) -> 1 | E9: 0.5 | F9: 1 | G9: 1 | H9: 1 | I9: 1 | J9: 1 | L9: 5 | M9: Uno importa bastante mas
B10: =IF(3>nA,"",INDEX(Configuracion!$E$13:$E$20,3)) -> Aplicación web | C10: =IF(3>nA,"",IF(E8="","",1/E8)) -> 3 | D10: =IF(3>nA,"",IF(E9="","",1/E9)) -> 2 | E10: =IF(3>nA,"",1) -> 1 | F10: 1 | G10: 1 | H10: 1 | I10: 1 | J10: 1 | L10: 7 | M10: Uno importa mucho mas
B11: =IF(4>nA,"",INDEX(Configuracion!$E$13:$E$20,4)) | C11: =IF(4>nA,"",IF(F8="","",1/F8)) | D11: =IF(4>nA,"",IF(F9="","",1/F9)) | E11: =IF(4>nA,"",IF(F10="","",1/F10)) | F11: =IF(4>nA,"",1) | G11: 1 | H11: 1 | I11: 1 | J11: 1 | L11: 9 | M11: Uno importa muchisimo mas
B12: =IF(5>nA,"",INDEX(Configuracion!$E$13:$E$20,5)) | C12: =IF(5>nA,"",IF(G8="","",1/G8)) | D12: =IF(5>nA,"",IF(G9="","",1/G9)) | E12: =IF(5>nA,"",IF(G10="","",1/G10)) | F12: =IF(5>nA,"",IF(G11="","",1/G11)) | G12: =IF(5>nA,"",1) | H12: 1 | I12: 1 | J12: 1 | L12: 1/3 | M12: Al reves: escribe =1/3
B13: =IF(6>nA,"",INDEX(Configuracion!$E$13:$E$20,6)) | C13: =IF(6>nA,"",IF(H8="","",1/H8)) | D13: =IF(6>nA,"",IF(H9="","",1/H9)) | E13: =IF(6>nA,"",IF(H10="","",1/H10)) | F13: =IF(6>nA,"",IF(H11="","",1/H11)) | G13: =IF(6>nA,"",IF(H12="","",1/H12)) | H13: =IF(6>nA,"",1) | I13: 1 | J13: 1 | L13: 1/5 | M13: Al reves, con mas fuerza: =1/5
B14: =IF(7>nA,"",INDEX(Configuracion!$E$13:$E$20,7)) | C14: =IF(7>nA,"",IF(I8="","",1/I8)) | D14: =IF(7>nA,"",IF(I9="","",1/I9)) | E14: =IF(7>nA,"",IF(I10="","",1/I10)) | F14: =IF(7>nA,"",IF(I11="","",1/I11)) | G14: =IF(7>nA,"",IF(I12="","",1/I12)) | H14: =IF(7>nA,"",IF(I13="","",1/I13)) | I14: =IF(7>nA,"",1) | J14: 1 | L14: 1/9 | M14: Al reves, al maximo: =1/9
B15: =IF(8>nA,"",INDEX(Configuracion!$E$13:$E$20,8)) | C15: =IF(8>nA,"",IF(J8="","",1/J8)) | D15: =IF(8>nA,"",IF(J9="","",1/J9)) | E15: =IF(8>nA,"",IF(J10="","",1/J10)) | F15: =IF(8>nA,"",IF(J11="","",1/J11)) | G15: =IF(8>nA,"",IF(J12="","",1/J12)) | H15: =IF(8>nA,"",IF(J13="","",1/J13)) | I15: =IF(8>nA,"",IF(J14="","",1/J14)) | J15: =IF(8>nA,"",1)
L16: Recuerda: escribe los inversos como formula (=1/3), nunca 1/3 solo, porque Excel lo lee como fecha.
B17: PASO 2 · Suma de cada columna
B18: Suma de la columna | C18: =IF(1>nA,"",SUM(INDEX(C$8:C$15,1):INDEX(C$8:C$15,nA))) -> 6 | D18: =IF(2>nA,"",SUM(INDEX(D$8:D$15,1):INDEX(D$8:D$15,nA))) -> 3.5 | E18: =IF(3>nA,"",SUM(INDEX(E$8:E$15,1):INDEX(E$8:E$15,nA))) -> 1.8333333 | F18: =IF(4>nA,"",SUM(INDEX(F$8:F$15,1):INDEX(F$8:F$15,nA))) | G18: =IF(5>nA,"",SUM(INDEX(G$8:G$15,1):INDEX(G$8:G$15,nA))) | H18: =IF(6>nA,"",SUM(INDEX(H$8:H$15,1):INDEX(H$8:H$15,nA))) | I18: =IF(7>nA,"",SUM(INDEX(I$8:I$15,1):INDEX(I$8:I$15,nA))) | J18: =IF(8>nA,"",SUM(INDEX(J$8:J$15,1):INDEX(J$8:J$15,nA)))
B20: PASO 3 · Matriz normalizada (cada celda dividida por la suma de SU columna)
B21: FILA \ COLUMNA | C21: =IF(1>nA,"",INDEX(Configuracion!$E$13:$E$20,1)) -> Nativas | D21: =IF(2>nA,"",INDEX(Configuracion!$E$13:$E$20,2)) -> Multiplataforma | E21: =IF(3>nA,"",INDEX(Configuracion!$E$13:$E$20,3)) -> Aplicación web | F21: =IF(4>nA,"",INDEX(Configuracion!$E$13:$E$20,4)) | G21: =IF(5>nA,"",INDEX(Configuracion!$E$13:$E$20,5)) | H21: =IF(6>nA,"",INDEX(Configuracion!$E$13:$E$20,6)) | I21: =IF(7>nA,"",INDEX(Configuracion!$E$13:$E$20,7)) | J21: =IF(8>nA,"",INDEX(Configuracion!$E$13:$E$20,8))
B22: =IF(1>nA,"",INDEX(Configuracion!$E$13:$E$20,1)) -> Nativas | C22: =IF(OR(1>nA,1>nA),"",C8/C$18) -> 0.16666667 | D22: =IF(OR(1>nA,2>nA),"",D8/D$18) -> 0.14285714 | E22: =IF(OR(1>nA,3>nA),"",E8/E$18) -> 0.18181818 | F22: =IF(OR(1>nA,4>nA),"",F8/F$18) | G22: =IF(OR(1>nA,5>nA),"",G8/G$18) | H22: =IF(OR(1>nA,6>nA),"",H8/H$18) | I22: =IF(OR(1>nA,7>nA),"",I8/I$18) | J22: =IF(OR(1>nA,8>nA),"",J8/J$18)
B23: =IF(2>nA,"",INDEX(Configuracion!$E$13:$E$20,2)) -> Multiplataforma | C23: =IF(OR(2>nA,1>nA),"",C9/C$18) -> 0.33333333 | D23: =IF(OR(2>nA,2>nA),"",D9/D$18) -> 0.28571429 | E23: =IF(OR(2>nA,3>nA),"",E9/E$18) -> 0.27272727 | F23: =IF(OR(2>nA,4>nA),"",F9/F$18) | G23: =IF(OR(2>nA,5>nA),"",G9/G$18) | H23: =IF(OR(2>nA,6>nA),"",H9/H$18) | I23: =IF(OR(2>nA,7>nA),"",I9/I$18) | J23: =IF(OR(2>nA,8>nA),"",J9/J$18)
B24: =IF(3>nA,"",INDEX(Configuracion!$E$13:$E$20,3)) -> Aplicación web | C24: =IF(OR(3>nA,1>nA),"",C10/C$18) -> 0.5 | D24: =IF(OR(3>nA,2>nA),"",D10/D$18) -> 0.57142857 | E24: =IF(OR(3>nA,3>nA),"",E10/E$18) -> 0.54545455 | F24: =IF(OR(3>nA,4>nA),"",F10/F$18) | G24: =IF(OR(3>nA,5>nA),"",G10/G$18) | H24: =IF(OR(3>nA,6>nA),"",H10/H$18) | I24: =IF(OR(3>nA,7>nA),"",I10/I$18) | J24: =IF(OR(3>nA,8>nA),"",J10/J$18)
B25: =IF(4>nA,"",INDEX(Configuracion!$E$13:$E$20,4)) | C25: =IF(OR(4>nA,1>nA),"",C11/C$18) | D25: =IF(OR(4>nA,2>nA),"",D11/D$18) | E25: =IF(OR(4>nA,3>nA),"",E11/E$18) | F25: =IF(OR(4>nA,4>nA),"",F11/F$18) | G25: =IF(OR(4>nA,5>nA),"",G11/G$18) | H25: =IF(OR(4>nA,6>nA),"",H11/H$18) | I25: =IF(OR(4>nA,7>nA),"",I11/I$18) | J25: =IF(OR(4>nA,8>nA),"",J11/J$18)
B26: =IF(5>nA,"",INDEX(Configuracion!$E$13:$E$20,5)) | C26: =IF(OR(5>nA,1>nA),"",C12/C$18) | D26: =IF(OR(5>nA,2>nA),"",D12/D$18) | E26: =IF(OR(5>nA,3>nA),"",E12/E$18) | F26: =IF(OR(5>nA,4>nA),"",F12/F$18) | G26: =IF(OR(5>nA,5>nA),"",G12/G$18) | H26: =IF(OR(5>nA,6>nA),"",H12/H$18) | I26: =IF(OR(5>nA,7>nA),"",I12/I$18) | J26: =IF(OR(5>nA,8>nA),"",J12/J$18)
B27: =IF(6>nA,"",INDEX(Configuracion!$E$13:$E$20,6)) | C27: =IF(OR(6>nA,1>nA),"",C13/C$18) | D27: =IF(OR(6>nA,2>nA),"",D13/D$18) | E27: =IF(OR(6>nA,3>nA),"",E13/E$18) | F27: =IF(OR(6>nA,4>nA),"",F13/F$18) | G27: =IF(OR(6>nA,5>nA),"",G13/G$18) | H27: =IF(OR(6>nA,6>nA),"",H13/H$18) | I27: =IF(OR(6>nA,7>nA),"",I13/I$18) | J27: =IF(OR(6>nA,8>nA),"",J13/J$18)
B28: =IF(7>nA,"",INDEX(Configuracion!$E$13:$E$20,7)) | C28: =IF(OR(7>nA,1>nA),"",C14/C$18) | D28: =IF(OR(7>nA,2>nA),"",D14/D$18) | E28: =IF(OR(7>nA,3>nA),"",E14/E$18) | F28: =IF(OR(7>nA,4>nA),"",F14/F$18) | G28: =IF(OR(7>nA,5>nA),"",G14/G$18) | H28: =IF(OR(7>nA,6>nA),"",H14/H$18) | I28: =IF(OR(7>nA,7>nA),"",I14/I$18) | J28: =IF(OR(7>nA,8>nA),"",J14/J$18)
B29: =IF(8>nA,"",INDEX(Configuracion!$E$13:$E$20,8)) | C29: =IF(OR(8>nA,1>nA),"",C15/C$18) | D29: =IF(OR(8>nA,2>nA),"",D15/D$18) | E29: =IF(OR(8>nA,3>nA),"",E15/E$18) | F29: =IF(OR(8>nA,4>nA),"",F15/F$18) | G29: =IF(OR(8>nA,5>nA),"",G15/G$18) | H29: =IF(OR(8>nA,6>nA),"",H15/H$18) | I29: =IF(OR(8>nA,7>nA),"",I15/I$18) | J29: =IF(OR(8>nA,8>nA),"",J15/J$18)
B31: PASO 4 · Vector de prioridad w (promedio de cada fila de la matriz normalizada)
B32: Elemento | C32: Peso w | D32: Peso % | E32: Que significa
B33: =IF(1>nA,"",INDEX(Configuracion!$E$13:$E$20,1)) -> Nativas | C33: =IF(1>nA,"",AVERAGE(INDEX($C22:$J22,1):INDEX($C22:$J22,nA))) -> 0.16378066 | D33: =IF(1>nA,"",C33) -> 0.16378066 | E33: =IF(1>nA,"","De cada 100 puntos de importancia, este se lleva "&TEXT(C33*100,"0,0")&".") -> De cada 100 puntos de importancia, este se lleva 16.
B34: =IF(2>nA,"",INDEX(Configuracion!$E$13:$E$20,2)) -> Multiplataforma | C34: =IF(2>nA,"",AVERAGE(INDEX($C23:$J23,1):INDEX($C23:$J23,nA))) -> 0.2972583 | D34: =IF(2>nA,"",C34) -> 0.2972583 | E34: =IF(2>nA,"","De cada 100 puntos de importancia, este se lleva "&TEXT(C34*100,"0,0")&".") -> De cada 100 puntos de importancia, este se lleva 30.
B35: =IF(3>nA,"",INDEX(Configuracion!$E$13:$E$20,3)) -> Aplicación web | C35: =IF(3>nA,"",AVERAGE(INDEX($C24:$J24,1):INDEX($C24:$J24,nA))) -> 0.53896104 | D35: =IF(3>nA,"",C35) -> 0.53896104 | E35: =IF(3>nA,"","De cada 100 puntos de importancia, este se lleva "&TEXT(C35*100,"0,0")&".") -> De cada 100 puntos de importancia, este se lleva 54.
B36: =IF(4>nA,"",INDEX(Configuracion!$E$13:$E$20,4)) | C36: =IF(4>nA,"",AVERAGE(INDEX($C25:$J25,1):INDEX($C25:$J25,nA))) | D36: =IF(4>nA,"",C36) | E36: =IF(4>nA,"","De cada 100 puntos de importancia, este se lleva "&TEXT(C36*100,"0,0")&".")
B37: =IF(5>nA,"",INDEX(Configuracion!$E$13:$E$20,5)) | C37: =IF(5>nA,"",AVERAGE(INDEX($C26:$J26,1):INDEX($C26:$J26,nA))) | D37: =IF(5>nA,"",C37) | E37: =IF(5>nA,"","De cada 100 puntos de importancia, este se lleva "&TEXT(C37*100,"0,0")&".")
B38: =IF(6>nA,"",INDEX(Configuracion!$E$13:$E$20,6)) | C38: =IF(6>nA,"",AVERAGE(INDEX($C27:$J27,1):INDEX($C27:$J27,nA))) | D38: =IF(6>nA,"",C38) | E38: =IF(6>nA,"","De cada 100 puntos de importancia, este se lleva "&TEXT(C38*100,"0,0")&".")
B39: =IF(7>nA,"",INDEX(Configuracion!$E$13:$E$20,7)) | C39: =IF(7>nA,"",AVERAGE(INDEX($C28:$J28,1):INDEX($C28:$J28,nA))) | D39: =IF(7>nA,"",C39) | E39: =IF(7>nA,"","De cada 100 puntos de importancia, este se lleva "&TEXT(C39*100,"0,0")&".")
B40: =IF(8>nA,"",INDEX(Configuracion!$E$13:$E$20,8)) | C40: =IF(8>nA,"",AVERAGE(INDEX($C29:$J29,1):INDEX($C29:$J29,nA))) | D40: =IF(8>nA,"",C40) | E40: =IF(8>nA,"","De cada 100 puntos de importancia, este se lleva "&TEXT(C40*100,"0,0")&".")
B41: Suma (debe dar 1) | C41: =SUM(INDEX($C$33:$C$40,1):INDEX($C$33:$C$40,nA)) -> 1
B43: w en horizontal (auxiliar) | C43: =IF(1>nA,"",$C$33) -> 0.16378066 | D43: =IF(2>nA,"",$C$34) -> 0.2972583 | E43: =IF(3>nA,"",$C$35) -> 0.53896104 | F43: =IF(4>nA,"",$C$36) | G43: =IF(5>nA,"",$C$37) | H43: =IF(6>nA,"",$C$38) | I43: =IF(7>nA,"",$C$39) | J43: =IF(8>nA,"",$C$40)
B45: PASO 5 · Comprobacion de consistencia
B46: Elemento | C46: Suma ponderada (A x w) | D46: Peso w | E46: Razon = (A x w) / w
...

Sheet C4
B2: Comparacion de las ALTERNATIVAS · criterio 4
B3: Compara las alternativas de a dos MIRANDO SOLO este criterio. Olvida los demas criterios por un momento.
B4: =IF(4>nC,"ESTA HOJA NO SE USA (solo definiste "&nC&" criterios)","Criterio 4: "&INDEX(Configuracion!$C$13:$C$20,4)) -> Criterio 4: Funciona sin internet
B6: PASO 1 · Matriz de comparacion por pares (llena SOLO las celdas amarillas) | L6: ESCALA | M6: Cuando usarla
B7: FILA \ COLUMNA | C7: =IF(1>nA,"",INDEX(Configuracion!$E$13:$E$20,1)) -> Nativas | D7: =IF(2>nA,"",INDEX(Configuracion!$E$13:$E$20,2)) -> Multiplataforma | E7: =IF(3>nA,"",INDEX(Configuracion!$E$13:$E$20,3)) -> Aplicación web | F7: =IF(4>nA,"",INDEX(Configuracion!$E$13:$E$20,4)) | G7: =IF(5>nA,"",INDEX(Configuracion!$E$13:$E$20,5)) | H7: =IF(6>nA,"",INDEX(Configuracion!$E$13:$E$20,6)) | I7: =IF(7>nA,"",INDEX(Configuracion!$E$13:$E$20,7)) | J7: =IF(8>nA,"",INDEX(Configuracion!$E$13:$E$20,8)) | L7: 1 | M7: Los dos importan igual
B8: =IF(1>nA,"",INDEX(Configuracion!$E$13:$E$20,1)) -> Nativas | C8: =IF(1>nA,"",1) -> 1 | D8: 1 | E8: 1 | F8: 1 | G8: 1 | H8: 1 | I8: 1 | J8: 1 | L8: 3 | M8: Uno importa algo mas
B9: =IF(2>nA,"",INDEX(Configuracion!$E$13:$E$20,2)) -> Multiplataforma | C9: =IF(2>nA,"",IF(D8="","",1/D8)) -> 1 | D9: =IF(2>nA,"",1) -> 1 | E9: 1 | F9: 1 | G9: 1 | H9: 1 | I9: 1 | J9: 1 | L9: 5 | M9: Uno importa bastante mas
B10: =IF(3>nA,"",INDEX(Configuracion!$E$13:$E$20,3)) -> Aplicación web | C10: =IF(3>nA,"",IF(E8="","",1/E8)) -> 1 | D10: =IF(3>nA,"",IF(E9="","",1/E9)) -> 1 | E10: =IF(3>nA,"",1) -> 1 | F10: 1 | G10: 1 | H10: 1 | I10: 1 | J10: 1 | L10: 7 | M10: Uno importa mucho mas
B11: =IF(4>nA,"",INDEX(Configuracion!$E$13:$E$20,4)) | C11: =IF(4>nA,"",IF(F8="","",1/F8)) | D11: =IF(4>nA,"",IF(F9="","",1/F9)) | E11: =IF(4>nA,"",IF(F10="","",1/F10)) | F11: =IF(4>nA,"",1) | G11: 1 | H11: 1 | I11: 1 | J11: 1 | L11: 9 | M11: Uno importa muchisimo mas
B12: =IF(5>nA,"",INDEX(Configuracion!$E$13:$E$20,5)) | C12: =IF(5>nA,"",IF(G8="","",1/G8)) | D12: =IF(5>nA,"",IF(G9="","",1/G9)) | E12: =IF(5>nA,"",IF(G10="","",1/G10)) | F12: =IF(5>nA,"",IF(G11="","",1/G11)) | G12: =IF(5>nA,"",1) | H12: 1 | I12: 1 | J12: 1 | L12: 1/3 | M12: Al reves: escribe =1/3
B13: =IF(6>nA,"",INDEX(Configuracion!$E$13:$E$20,6)) | C13: =IF(6>nA,"",IF(H8="","",1/H8)) | D13: =IF(6>nA,"",IF(H9="","",1/H9)) | E13: =IF(6>nA,"",IF(H10="","",1/H10)) | F13: =IF(6>nA,"",IF(H11="","",1/H11)) | G13: =IF(6>nA,"",IF(H12="","",1/H12)) | H13: =IF(6>nA,"",1) | I13: 1 | J13: 1 | L13: 1/5 | M13: Al reves, con mas fuerza: =1/5
B14: =IF(7>nA,"",INDEX(Configuracion!$E$13:$E$20,7)) | C14: =IF(7>nA,"",IF(I8="","",1/I8)) | D14: =IF(7>nA,"",IF(I9="","",1/I9)) | E14: =IF(7>nA,"",IF(I10="","",1/I10)) | F14: =IF(7>nA,"",IF(I11="","",1/I11)) | G14: =IF(7>nA,"",IF(I12="","",1/I12)) | H14: =IF(7>nA,"",IF(I13="","",1/I13)) | I14: =IF(7>nA,"",1) | J14: 1 | L14: 1/9 | M14: Al reves, al maximo: =1/9
B15: =IF(8>nA,"",INDEX(Configuracion!$E$13:$E$20,8)) | C15: =IF(8>nA,"",IF(J8="","",1/J8)) | D15: =IF(8>nA,"",IF(J9="","",1/J9)) | E15: =IF(8>nA,"",IF(J10="","",1/J10)) | F15: =IF(8>nA,"",IF(J11="","",1/J11)) | G15: =IF(8>nA,"",IF(J12="","",1/J12)) | H15: =IF(8>nA,"",IF(J13="","",1/J13)) | I15: =IF(8>nA,"",IF(J14="","",1/J14)) | J15: =IF(8>nA,"",1)
L16: Recuerda: escribe los inversos como formula (=1/3), nunca 1/3 solo, porque Excel lo lee como fecha.
B17: PASO 2 · Suma de cada columna
B18: Suma de la columna | C18: =IF(1>nA,"",SUM(INDEX(C$8:C$15,1):INDEX(C$8:C$15,nA))) -> 3 | D18: =IF(2>nA,"",SUM(INDEX(D$8:D$15,1):INDEX(D$8:D$15,nA))) -> 3 | E18: =IF(3>nA,"",SUM(INDEX(E$8:E$15,1):INDEX(E$8:E$15,nA))) -> 3 | F18: =IF(4>nA,"",SUM(INDEX(F$8:F$15,1):INDEX(F$8:F$15,nA))) | G18: =IF(5>nA,"",SUM(INDEX(G$8:G$15,1):INDEX(G$8:G$15,nA))) | H18: =IF(6>nA,"",SUM(INDEX(H$8:H$15,1):INDEX(H$8:H$15,nA))) | I18: =IF(7>nA,"",SUM(INDEX(I$8:I$15,1):INDEX(I$8:I$15,nA))) | J18: =IF(8>nA,"",SUM(INDEX(J$8:J$15,1):INDEX(J$8:J$15,nA)))
B20: PASO 3 · Matriz normalizada (cada celda dividida por la suma de SU columna)
B21: FILA \ COLUMNA | C21: =IF(1>nA,"",INDEX(Configuracion!$E$13:$E$20,1)) -> Nativas | D21: =IF(2>nA,"",INDEX(Configuracion!$E$13:$E$20,2)) -> Multiplataforma | E21: =IF(3>nA,"",INDEX(Configuracion!$E$13:$E$20,3)) -> Aplicación web | F21: =IF(4>nA,"",INDEX(Configuracion!$E$13:$E$20,4)) | G21: =IF(5>nA,"",INDEX(Configuracion!$E$13:$E$20,5)) | H21: =IF(6>nA,"",INDEX(Configuracion!$E$13:$E$20,6)) | I21: =IF(7>nA,"",INDEX(Configuracion!$E$13:$E$20,7)) | J21: =IF(8>nA,"",INDEX(Configuracion!$E$13:$E$20,8))
B22: =IF(1>nA,"",INDEX(Configuracion!$E$13:$E$20,1)) -> Nativas | C22: =IF(OR(1>nA,1>nA),"",C8/C$18) -> 0.33333333 | D22: =IF(OR(1>nA,2>nA),"",D8/D$18) -> 0.33333333 | E22: =IF(OR(1>nA,3>nA),"",E8/E$18) -> 0.33333333 | F22: =IF(OR(1>nA,4>nA),"",F8/F$18) | G22: =IF(OR(1>nA,5>nA),"",G8/G$18) | H22: =IF(OR(1>nA,6>nA),"",H8/H$18) | I22: =IF(OR(1>nA,7>nA),"",I8/I$18) | J22: =IF(OR(1>nA,8>nA),"",J8/J$18)
B23: =IF(2>nA,"",INDEX(Configuracion!$E$13:$E$20,2)) -> Multiplataforma | C23: =IF(OR(2>nA,1>nA),"",C9/C$18) -> 0.33333333 | D23: =IF(OR(2>nA,2>nA),"",D9/D$18) -> 0.33333333 | E23: =IF(OR(2>nA,3>nA),"",E9/E$18) -> 0.33333333 | F23: =IF(OR(2>nA,4>nA),"",F9/F$18) | G23: =IF(OR(2>nA,5>nA),"",G9/G$18) | H23: =IF(OR(2>nA,6>nA),"",H9/H$18) | I23: =IF(OR(2>nA,7>nA),"",I9/I$18) | J23: =IF(OR(2>nA,8>nA),"",J9/J$18)
B24: =IF(3>nA,"",INDEX(Configuracion!$E$13:$E$20,3)) -> Aplicación web | C24: =IF(OR(3>nA,1>nA),"",C10/C$18) -> 0.33333333 | D24: =IF(OR(3>nA,2>nA),"",D10/D$18) -> 0.33333333 | E24: =IF(OR(3>nA,3>nA),"",E10/E$18) -> 0.33333333 | F24: =IF(OR(3>nA,4>nA),"",F10/F$18) | G24: =IF(OR(3>nA,5>nA),"",G10/G$18) | H24: =IF(OR(3>nA,6>nA),"",H10/H$18) | I24: =IF(OR(3>nA,7>nA),"",I10/I$18) | J24: =IF(OR(3>nA,8>nA),"",J10/J$18)
B25: =IF(4>nA,"",INDEX(Configuracion!$E$13:$E$20,4)) | C25: =IF(OR(4>nA,1>nA),"",C11/C$18) | D25: =IF(OR(4>nA,2>nA),"",D11/D$18) | E25: =IF(OR(4>nA,3>nA),"",E11/E$18) | F25: =IF(OR(4>nA,4>nA),"",F11/F$18) | G25: =IF(OR(4>nA,5>nA),"",G11/G$18) | H25: =IF(OR(4>nA,6>nA),"",H11/H$18) | I25: =IF(OR(4>nA,7>nA),"",I11/I$18) | J25: =IF(OR(4>nA,8>nA),"",J11/J$18)
B26: =IF(5>nA,"",INDEX(Configuracion!$E$13:$E$20,5)) | C26: =IF(OR(5>nA,1>nA),"",C12/C$18) | D26: =IF(OR(5>nA,2>nA),"",D12/D$18) | E26: =IF(OR(5>nA,3>nA),"",E12/E$18) | F26: =IF(OR(5>nA,4>nA),"",F12/F$18) | G26: =IF(OR(5>nA,5>nA),"",G12/G$18) | H26: =IF(OR(5>nA,6>nA),"",H12/H$18) | I26: =IF(OR(5>nA,7>nA),"",I12/I$18) | J26: =IF(OR(5>nA,8>nA),"",J12/J$18)
B27: =IF(6>nA,"",INDEX(Configuracion!$E$13:$E$20,6)) | C27: =IF(OR(6>nA,1>nA),"",C13/C$18) | D27: =IF(OR(6>nA,2>nA),"",D13/D$18) | E27: =IF(OR(6>nA,3>nA),"",E13/E$18) | F27: =IF(OR(6>nA,4>nA),"",F13/F$18) | G27: =IF(OR(6>nA,5>nA),"",G13/G$18) | H27: =IF(OR(6>nA,6>nA),"",H13/H$18) | I27: =IF(OR(6>nA,7>nA),"",I13/I$18) | J27: =IF(OR(6>nA,8>nA),"",J13/J$18)
B28: =IF(7>nA,"",INDEX(Configuracion!$E$13:$E$20,7)) | C28: =IF(OR(7>nA,1>nA),"",C14/C$18) | D28: =IF(OR(7>nA,2>nA),"",D14/D$18) | E28: =IF(OR(7>nA,3>nA),"",E14/E$18) | F28: =IF(OR(7>nA,4>nA),"",F14/F$18) | G28: =IF(OR(7>nA,5>nA),"",G14/G$18) | H28: =IF(OR(7>nA,6>nA),"",H14/H$18) | I28: =IF(OR(7>nA,7>nA),"",I14/I$18) | J28: =IF(OR(7>nA,8>nA),"",J14/J$18)
B29: =IF(8>nA,"",INDEX(Configuracion!$E$13:$E$20,8)) | C29: =IF(OR(8>nA,1>nA),"",C15/C$18) | D29: =IF(OR(8>nA,2>nA),"",D15/D$18) | E29: =IF(OR(8>nA,3>nA),"",E15/E$18) | F29: =IF(OR(8>nA,4>nA),"",F15/F$18) | G29: =IF(OR(8>nA,5>nA),"",G15/G$18) | H29: =IF(OR(8>nA,6>nA),"",H15/H$18) | I29: =IF(OR(8>nA,7>nA),"",I15/I$18) | J29: =IF(OR(8>nA,8>nA),"",J15/J$18)
B31: PASO 4 · Vector de prioridad w (promedio de cada fila de la matriz normalizada)
B32: Elemento | C32: Peso w | D32: Peso % | E32: Que significa
B33: =IF(1>nA,"",INDEX(Configuracion!$E$13:$E$20,1)) -> Nativas | C33: =IF(1>nA,"",AVERAGE(INDEX($C22:$J22,1):INDEX($C22:$J22,nA))) -> 0.33333333 | D33: =IF(1>nA,"",C33) -> 0.33333333 | E33: =IF(1>nA,"","De cada 100 puntos de importancia, este se lleva "&TEXT(C33*100,"0,0")&".") -> De cada 100 puntos de importancia, este se lleva 33.
B34: =IF(2>nA,"",INDEX(Configuracion!$E$13:$E$20,2)) -> Multiplataforma | C34: =IF(2>nA,"",AVERAGE(INDEX($C23:$J23,1):INDEX($C23:$J23,nA))) -> 0.33333333 | D34: =IF(2>nA,"",C34) -> 0.33333333 | E34: =IF(2>nA,"","De cada 100 puntos de importancia, este se lleva "&TEXT(C34*100,"0,0")&".") -> De cada 100 puntos de importancia, este se lleva 33.
B35: =IF(3>nA,"",INDEX(Configuracion!$E$13:$E$20,3)) -> Aplicación web | C35: =IF(3>nA,"",AVERAGE(INDEX($C24:$J24,1):INDEX($C24:$J24,nA))) -> 0.33333333 | D35: =IF(3>nA,"",C35) -> 0.33333333 | E35: =IF(3>nA,"","De cada 100 puntos de importancia, este se lleva "&TEXT(C35*100,"0,0")&".") -> De cada 100 puntos de importancia, este se lleva 33.
B36: =IF(4>nA,"",INDEX(Configuracion!$E$13:$E$20,4)) | C36: =IF(4>nA,"",AVERAGE(INDEX($C25:$J25,1):INDEX($C25:$J25,nA))) | D36: =IF(4>nA,"",C36) | E36: =IF(4>nA,"","De cada 100 puntos de importancia, este se lleva "&TEXT(C36*100,"0,0")&".")
B37: =IF(5>nA,"",INDEX(Configuracion!$E$13:$E$20,5)) | C37: =IF(5>nA,"",AVERAGE(INDEX($C26:$J26,1):INDEX($C26:$J26,nA))) | D37: =IF(5>nA,"",C37) | E37: =IF(5>nA,"","De cada 100 puntos de importancia, este se lleva "&TEXT(C37*100,"0,0")&".")
B38: =IF(6>nA,"",INDEX(Configuracion!$E$13:$E$20,6)) | C38: =IF(6>nA,"",AVERAGE(INDEX($C27:$J27,1):INDEX($C27:$J27,nA))) | D38: =IF(6>nA,"",C38) | E38: =IF(6>nA,"","De cada 100 puntos de importancia, este se lleva "&TEXT(C38*100,"0,0")&".")
B39: =IF(7>nA,"",INDEX(Configuracion!$E$13:$E$20,7)) | C39: =IF(7>nA,"",AVERAGE(INDEX($C28:$J28,1):INDEX($C28:$J28,nA))) | D39: =IF(7>nA,"",C39) | E39: =IF(7>nA,"","De cada 100 puntos de importancia, este se lleva "&TEXT(C39*100,"0,0")&".")
B40: =IF(8>nA,"",INDEX(Configuracion!$E$13:$E$20,8)) | C40: =IF(8>nA,"",AVERAGE(INDEX($C29:$J29,1):INDEX($C29:$J29,nA))) | D40: =IF(8>nA,"",C40) | E40: =IF(8>nA,"","De cada 100 puntos de importancia, este se lleva "&TEXT(C40*100,"0,0")&".")
B41: Suma (debe dar 1) | C41: =SUM(INDEX($C$33:$C$40,1):INDEX($C$33:$C$40,nA)) -> 1
B43: w en horizontal (auxiliar) | C43: =IF(1>nA,"",$C$33) -> 0.33333333 | D43: =IF(2>nA,"",$C$34) -> 0.33333333 | E43: =IF(3>nA,"",$C$35) -> 0.33333333 | F43: =IF(4>nA,"",$C$36) | G43: =IF(5>nA,"",$C$37) | H43: =IF(6>nA,"",$C$38) | I43: =IF(7>nA,"",$C$39) | J43: =IF(8>nA,"",$C$40)
B45: PASO 5 · Comprobacion de consistencia
B46: Elemento | C46: Suma ponderada (A x w) | D46: Peso w | E46: Razon = (A x w) / w
...

Sheet C5
B2: Comparacion de las ALTERNATIVAS · criterio 5
B3: Compara las alternativas de a dos MIRANDO SOLO este criterio. Olvida los demas criterios por un momento.
B4: =IF(5>nC,"ESTA HOJA NO SE USA (solo definiste "&nC&" criterios)","Criterio 5: "&INDEX(Configuracion!$C$13:$C$20,5)) -> Criterio 5: Seguridad
B6: PASO 1 · Matriz de comparacion por pares (llena SOLO las celdas amarillas) | L6: ESCALA | M6: Cuando usarla
