Workbook

Sheet Funciones
A1: PLANTILLA DE CÁLCULO DE PUNTOS DE FUNCIÓN
A2: Sistema / Proyecto: SIGRA Equipo: #B
A4: ID | B4: Función / Requisito | C4: Tipo (EI/EO/EQ/ILF/EIF) | D4: Descripción / Justificación | E4: DET | F4: FTR / RET | G4: Complejidad | H4: Peso | I4: Puntos de Función | J4: Responsable
A5: 1 | B5: registrar profesores | C5: ILF | D5: Archivo lógico mantenido por el sistema. DET: Nombre completo, Correo institucional, Cédula, Estado (4). RET=1. | E5: 4 | F5: 1 | G5: Baja | H5: =IF(OR(C5="",G5=""),"",IF(C5="EI",IF(G5="Baja",3,IF(G5="Media",4,6)),IF(C5="EO",IF(G5="Baja",4,IF(G5="Media",5,7)),IF(C5="EQ",IF(G5="Baja",3,IF(G5="Media",4,6)),IF(C5="ILF",IF(G5="Baja",7,IF(G5="Media",10,15)),IF(C5="EIF",IF(G5="Baja",5,IF(G5="Media",7,10)),"")))))) -> 7 | I5: =IF(H5="","",H5) -> 7 | J5: Jean Paul Ortiz
A6: 2 | B6: registrar profesores | C6: EI | D6: Campos: Nombre completo, Correo, Cédula (3) + botón "Registrar" (1) + mensaje éxito/error (1). FTR: Profesor (mantiene) = 1. | E6: 5 | F6: 1 | G6: Baja | H6: 3 | I6: 3 | J6: Jean Paul Ortiz
A7: 3 | B7: consultar profesores | C7: EQ | D7: Campos mostrados: Nombre, Correo, Cédula, Estado (4) + filtro de búsqueda (1). FTR: Profesor (referencia) = 1. | E7: 5 | F7: 1 | G7: Baja | H7: =IF(OR(C7="",G7=""),"",IF(C7="EI",IF(G7="Baja",3,IF(G7="Media",4,6)),IF(C7="EO",IF(G7="Baja",4,IF(G7="Media",5,7)),IF(C7="EQ",IF(G7="Baja",3,IF(G7="Media",4,6)),IF(C7="ILF",IF(G7="Baja",7,IF(G7="Media",10,15)),IF(C7="EIF",IF(G7="Baja",5,IF(G7="Media",7,10)),"")))))) -> 3 | I7: =IF(H7="","",H7) -> 3 | J7: Jean Paul Ortiz
A8: 4 | B8: modificar profesores | C8: EI | D8: Nombre, Correo (editables, 2) + Cédula (mostrada, bloqueada, 1) + botón "Guardar" (1) + mensaje (1). FTR: Profesor (mantiene) = 1. | E8: 5 | F8: 1 | G8: Baja | H8: =IF(OR(C8="",G8=""),"",IF(C8="EI",IF(G8="Baja",3,IF(G8="Media",4,6)),IF(C8="EO",IF(G8="Baja",4,IF(G8="Media",5,7)),IF(C8="EQ",IF(G8="Baja",3,IF(G8="Media",4,6)),IF(C8="ILF",IF(G8="Baja",7,IF(G8="Media",10,15)),IF(C8="EIF",IF(G8="Baja",5,IF(G8="Media",7,10)),"")))))) -> 3 | I8: =IF(H8="","",H8) -> 3 | J8: Jean Paul Ortiz
A9: 5 | B9: inactivar profesores | C9: EI | D9: Botón "Inactivar" (1) + mensaje éxito/error con motivo (1). FTR: Profesor (mantiene) + Asignatura (referencia) = 2. | E9: 2 | F9: 2 | G9: Baja | H9: =IF(OR(C9="",G9=""),"",IF(C9="EI",IF(G9="Baja",3,IF(G9="Media",4,6)),IF(C9="EO",IF(G9="Baja",4,IF(G9="Media",5,7)),IF(C9="EQ",IF(G9="Baja",3,IF(G9="Media",4,6)),IF(C9="ILF",IF(G9="Baja",7,IF(G9="Media",10,15)),IF(C9="EIF",IF(G9="Baja",5,IF(G9="Media",7,10)),"")))))) -> 3 | I9: =IF(H9="","",H9) -> 3 | J9: Jean Paul Ortiz
A10: 6 | B10: registrar programas academicos | C10: ILF | D10: Archivo lógico mantenido. DET: Nombre, Código, Estado (3). RET=1. | E10: 3 | F10: 1 | G10: Baja | H10: =IF(OR(C10="",G10=""),"",IF(C10="EI",IF(G10="Baja",3,IF(G10="Media",4,6)),IF(C10="EO",IF(G10="Baja",4,IF(G10="Media",5,7)),IF(C10="EQ",IF(G10="Baja",3,IF(G10="Media",4,6)),IF(C10="ILF",IF(G10="Baja",7,IF(G10="Media",10,15)),IF(C10="EIF",IF(G10="Baja",5,IF(G10="Media",7,10)),"")))))) -> 7 | I10: =IF(H10="","",H10) -> 7 | J10: Jean Paul Ortiz
A11: 7 | B11: registrar programas academicos | C11: EI | D11: Nombre, Código (2) + botón "Registrar" (1) + mensaje (1). FTR: Programa (mantiene) = 1. | E11: 4 | F11: 1 | G11: Baja | H11: 3 | I11: 3 | J11: Jean Paul Ortiz
A12: 8 | B12: consultar programas academicos | C12: EQ | D12: Nombre, Código, Estado (3) + filtro (1). FTR: Programa (referencia) = 1. | E12: 4 | F12: 1 | G12: Baja | H12: =IF(OR(C12="",G12=""),"",IF(C12="EI",IF(G12="Baja",3,IF(G12="Media",4,6)),IF(C12="EO",IF(G12="Baja",4,IF(G12="Media",5,7)),IF(C12="EQ",IF(G12="Baja",3,IF(G12="Media",4,6)),IF(C12="ILF",IF(G12="Baja",7,IF(G12="Media",10,15)),IF(C12="EIF",IF(G12="Baja",5,IF(G12="Media",7,10)),"")))))) -> 3 | I12: =IF(H12="","",H12) -> 3 | J12: Jean Paul Ortiz
A13: 9 | B13: modificar programas academicos | C13: EI | D13: El Administrador modifica el nombre de un programa académico existente. El código no puede modificarse. Es una entrada que mantiene/actualiza información del ILF Programa Académico. | E13: 4 | F13: 1 | G13: Baja | H13: =IF(OR(C13="",G13=""),"",IF(C13="EI",IF(G13="Baja",3,IF(G13="Media",4,6)),IF(C13="EO",IF(G13="Baja",4,IF(G13="Media",5,7)),IF(C13="EQ",IF(G13="Baja",3,IF(G13="Media",4,6)),IF(C13="ILF",IF(G13="Baja",7,IF(G13="Media",10,15)),IF(C13="EIF",IF(G13="Baja",5,IF(G13="Media",7,10)),"")))))) -> 3 | I13: =IF(H13="","",H13) -> 3 | J13: Juan Jose Narvaez
A14: 10 | B14: inactivar programas academicos | C14: EI | D14: El Administrador solicita la inactivación de un programa. El sistema verifica que no tenga asignaturas activas y, si cumple, cambia su estado mediante eliminación lógica. | E14: 4 | F14: 2 | G14: Baja | H14: =IF(OR(C14="",G14=""),"",IF(C14="EI",IF(G14="Baja",3,IF(G14="Media",4,6)),IF(C14="EO",IF(G14="Baja",4,IF(G14="Media",5,7)),IF(C14="EQ",IF(G14="Baja",3,IF(G14="Media",4,6)),IF(C14="ILF",IF(G14="Baja",7,IF(G14="Media",10,15)),IF(C14="EIF",IF(G14="Baja",5,IF(G14="Media",7,10)),"")))))) -> 3 | I14: =IF(H14="","",H14) -> 3 | J14: Juan Jose Narvaez
A15: 11 | B15: registrar materias | C15: ILF | D15: Archivo lógico mantenido. DET: Nombre, Código, Programa asociado | E15: 5 | F15: 2 | G15: Baja | H15: 7 | I15: 7 | J15: Juan Jose Narvaez
A16: 12 | B16: registrar materias | C16: EI | D16: Campos: Nombre, Código, Programa académico (3) + botón (1) + mensaje (1). | E16: 5 | F16: 2 | G16: Media | H16: =IF(OR(C16="",G16=""),"",IF(C16="EI",IF(G16="Baja",3,IF(G16="Media",4,6)),IF(C16="EO",IF(G16="Baja",4,IF(G16="Media",5,7)),IF(C16="EQ",IF(G16="Baja",3,IF(G16="Media",4,6)),IF(C16="ILF",IF(G16="Baja",7,IF(G16="Media",10,15)),IF(C16="EIF",IF(G16="Baja",5,IF(G16="Media",7,10)),"")))))) -> 4 | I16: =IF(H16="","",H16) -> 4 | J16: Juan Jose Narvaez
A17: 13 | B17: consultar materias | C17: EQ | D17: El Administrador o Profesor consulta el listado de asignaturas utilizando filtros por programa, nombre, código o estado. | E17: 7 | F17: 1 | G17: Baja | H17: =IF(OR(C17="",G17=""),"",IF(C17="EI",IF(G17="Baja",3,IF(G17="Media",4,6)),IF(C17="EO",IF(G17="Baja",4,IF(G17="Media",5,7)),IF(C17="EQ",IF(G17="Baja",3,IF(G17="Media",4,6)),IF(C17="ILF",IF(G17="Baja",7,IF(G17="Media",10,15)),IF(C17="EIF",IF(G17="Baja",5,IF(G17="Media",7,10)),"")))))) -> 3 | I17: =IF(H17="","",H17) -> 3 | J17: Juan Jose Narvaez
A18: 14 | B18: modificar materias | C18: EI | D18: El Administrador modifica el nombre de una asignatura existente. El código y el programa académico asociado permanecen sin cambios. | E18: 5 | F18: 1 | G18: Baja | H18: =IF(OR(C18="",G18=""),"",IF(C18="EI",IF(G18="Baja",3,IF(G18="Media",4,6)),IF(C18="EO",IF(G18="Baja",4,IF(G18="Media",5,7)),IF(C18="EQ",IF(G18="Baja",3,IF(G18="Media",4,6)),IF(C18="ILF",IF(G18="Baja",7,IF(G18="Media",10,15)),IF(C18="EIF",IF(G18="Baja",5,IF(G18="Media",7,10)),"")))))) -> 3 | I18: =IF(H18="","",H18) -> 3 | J18: Juan Jose Narvaez
A19: 15 | B19: activar/inactivar materias | C19: EI | D19: El Administrador cambia una asignatura Activa/Inactiva. Antes debe verificar que no existan evaluaciones abiertas del semestre para eliminar; si existen, requiere confirmación explícita. | E19: 2 | F19: 3 | G19: Baja | H19: =IF(OR(C19="",G19=""),"",IF(C19="EI",IF(G19="Baja",3,IF(G19="Media",4,6)),IF(C19="EO",IF(G19="Baja",4,IF(G19="Media",5,7)),IF(C19="EQ",IF(G19="Baja",3,IF(G19="Media",4,6)),IF(C19="ILF",IF(G19="Baja",7,IF(G19="Media",10,15)),IF(C19="EIF",IF(G19="Baja",5,IF(G19="Media",7,10)),"")))))) -> 3 | I19: =IF(H19="","",H19) -> 3 | J19: Juan Jose Narvaez
A20: 16 | B20: autorizacion de usuarios | C20: ILF | D20: Guarda los datos del usuario: correo, contraseña, rol y estado. Es un solo bloque de datos. | E20: 4 | F20: 1 | G20: Baja | H20: =IF(OR(C20="",G20=""),"",IF(C20="EI",IF(G20="Baja",3,IF(G20="Media",4,6)),IF(C20="EO",IF(G20="Baja",4,IF(G20="Media",5,7)),IF(C20="EQ",IF(G20="Baja",3,IF(G20="Media",4,6)),IF(C20="ILF",IF(G20="Baja",7,IF(G20="Media",10,15)),IF(C20="EIF",IF(G20="Baja",5,IF(G20="Media",7,10)),"")))))) -> 7 | I20: =IF(H20="","",H20) -> 7 | J20: Santiago Torres
A21: 17 | B21: autorizacion de usuarios | C21: EI | D21: El admin le da acceso a un usuario asignándole un rol. Campos + botón + mensaje. Solo usa el archivo de usuario. | E21: 4 | F21: 1 | G21: Baja | H21: =IF(OR(C21="",G21=""),"",IF(C21="EI",IF(G21="Baja",3,IF(G21="Media",4,6)),IF(C21="EO",IF(G21="Baja",4,IF(G21="Media",5,7)),IF(C21="EQ",IF(G21="Baja",3,IF(G21="Media",4,6)),IF(C21="ILF",IF(G21="Baja",7,IF(G21="Media",10,15)),IF(C21="EIF",IF(G21="Baja",5,IF(G21="Media",7,10)),"")))))) -> 3 | I21: =IF(H21="","",H21) -> 3 | J21: Santiago Torres
A22: 18 | B22: Control de acceso basado en roles (RBAC) | D22: NO es un proceso elemental transaccional: es una regla de autorización transversal aplicada dentro de TODOS los demás EI/EO/EQ del sistema (oculta opciones de menú y rechaza solicitudes 403 según el rol). No mantiene ni consulta por sí sola un archivo de negocio de forma independiente, por lo que no genera puntos de función propios. | H22: =IF(OR(C22="",G22=""),"",IF(C22="EI",IF(G22="Baja",3,IF(G22="Media",4,6)),IF(C22="EO",IF(G22="Baja",4,IF(G22="Media",5,7)),IF(C22="EQ",IF(G22="Baja",3,IF(G22="Media",4,6)),IF(C22="ILF",IF(G22="Baja",7,IF(G22="Media",10,15)),IF(C22="EIF",IF(G22="Baja",5,IF(G22="Media",7,10)),"")))))) | I22: =IF(H22="","",H22)
A23: 19 | B23: Registrar RA | C23: ILF | D23: Guarda cada resultado de aprendizaje: código, descripción, umbral y asignatura. | E23: 4 | F23: 1 | G23: Baja | H23: =IF(OR(C23="",G23=""),"",IF(C23="EI",IF(G23="Baja",3,IF(G23="Media",4,6)),IF(C23="EO",IF(G23="Baja",4,IF(G23="Media",5,7)),IF(C23="EQ",IF(G23="Baja",3,IF(G23="Media",4,6)),IF(C23="ILF",IF(G23="Baja",7,IF(G23="Media",10,15)),IF(C23="EIF",IF(G23="Baja",5,IF(G23="Media",7,10)),"")))))) -> 7 | I23: =IF(H23="","",H23) -> 7 | J23: Santiago Torres
A24: 20 | B24: Registrar RA | C24: EI | D24: Se crea un RA nuevo con sus datos y se asocia a una asignatura. Toca el archivo de RA y el de asignatura. | E24: 6 | F24: 2 | G24: Media | H24: =IF(OR(C24="",G24=""),"",IF(C24="EI",IF(G24="Baja",3,IF(G24="Media",4,6)),IF(C24="EO",IF(G24="Baja",4,IF(G24="Media",5,7)),IF(C24="EQ",IF(G24="Baja",3,IF(G24="Media",4,6)),IF(C24="ILF",IF(G24="Baja",7,IF(G24="Media",10,15)),IF(C24="EIF",IF(G24="Baja",5,IF(G24="Media",7,10)),"")))))) -> 4 | I24: =IF(H24="","",H24) -> 4 | J24: Santiago Torres
A25: 21 | B25: Consultar RA | C25: EQ | D25: Se muestra la lista de RA con filtro de búsqueda. Consulta el archivo de RA y el de asignatura. | E25: 6 | F25: 2 | G25: Media | H25: =IF(OR(C25="",G25=""),"",IF(C25="EI",IF(G25="Baja",3,IF(G25="Media",4,6)),IF(C25="EO",IF(G25="Baja",4,IF(G25="Media",5,7)),IF(C25="EQ",IF(G25="Baja",3,IF(G25="Media",4,6)),IF(C25="ILF",IF(G25="Baja",7,IF(G25="Media",10,15)),IF(C25="EIF",IF(G25="Baja",5,IF(G25="Media",7,10)),"")))))) -> 4 | I25: =IF(H25="","",H25) -> 4 | J25: Santiago Torres
A26: 22 | B26: Modificar/Inactivar RA | C26: EI | D26: Se edita la descripción o el estado de un RA. Solo usa el archivo de RA. | E26: 4 | F26: 1 | G26: Baja | H26: =IF(OR(C26="",G26=""),"",IF(C26="EI",IF(G26="Baja",3,IF(G26="Media",4,6)),IF(C26="EO",IF(G26="Baja",4,IF(G26="Media",5,7)),IF(C26="EQ",IF(G26="Baja",3,IF(G26="Media",4,6)),IF(C26="ILF",IF(G26="Baja",7,IF(G26="Media",10,15)),IF(C26="EIF",IF(G26="Baja",5,IF(G26="Media",7,10)),"")))))) -> 3 | I26: =IF(H26="","",H26) -> 3 | J26: Santiago Torres
A27: 23 | B27: Asignación docente de asignaturas | C27: EI | D27: Se asigna un profesor a una asignatura. Usa el archivo de profesor y el de asignatura. | E27: 4 | F27: 2 | G27: Baja | H27: =IF(OR(C27="",G27=""),"",IF(C27="EI",IF(G27="Baja",3,IF(G27="Media",4,6)),IF(C27="EO",IF(G27="Baja",4,IF(G27="Media",5,7)),IF(C27="EQ",IF(G27="Baja",3,IF(G27="Media",4,6)),IF(C27="ILF",IF(G27="Baja",7,IF(G27="Media",10,15)),IF(C27="EIF",IF(G27="Baja",5,IF(G27="Media",7,10)),"")))))) -> 3 | I27: =IF(H27="","",H27) -> 3 | J27: Santiago Torres
A28: 24 | B28: Matrícula de estudiantes | C28: ILF | D28: Guarda qué estudiante está matriculado en qué asignatura y cuándo. | E28: 4 | F28: 1 | G28: Baja | H28: =IF(OR(C28="",G28=""),"",IF(C28="EI",IF(G28="Baja",3,IF(G28="Media",4,6)),IF(C28="EO",IF(G28="Baja",4,IF(G28="Media",5,7)),IF(C28="EQ",IF(G28="Baja",3,IF(G28="Media",4,6)),IF(C28="ILF",IF(G28="Baja",7,IF(G28="Media",10,15)),IF(C28="EIF",IF(G28="Baja",5,IF(G28="Media",7,10)),"")))))) -> 7 | I28: =IF(H28="","",H28) -> 7 | J28: Santiago Torres
A29: 25 | B29: Matrícula de estudiantes | C29: EI | D29: Se matricula un estudiante en una asignatura. Toca tres archivos: matrícula, estudiante y asignatura. | E29: 4 | F29: 3 | G29: Media | H29: =IF(OR(C29="",G29=""),"",IF(C29="EI",IF(G29="Baja",3,IF(G29="Media",4,6)),IF(C29="EO",IF(G29="Baja",4,IF(G29="Media",5,7)),IF(C29="EQ",IF(G29="Baja",3,IF(G29="Media",4,6)),IF(C29="ILF",IF(G29="Baja",7,IF(G29="Media",10,15)),IF(C29="EIF",IF(G29="Baja",5,IF(G29="Media",7,10)),"")))))) -> 4 | I29: =IF(H29="","",H29) -> 4 | J29: Santiago Torres
A30: 26 | B30: desvinculación de estudiantes | C30: EI | D30: Se retira a un estudiante de una asignatura, con motivo. Usa el archivo de matrícula y el de estudiante. | E30: 3 | F30: 2 | G30: Baja | H30: =IF(OR(C30="",G30=""),"",IF(C30="EI",IF(G30="Baja",3,IF(G30="Media",4,6)),IF(C30="EO",IF(G30="Baja",4,IF(G30="Media",5,7)),IF(C30="EQ",IF(G30="Baja",3,IF(G30="Media",4,6)),IF(C30="ILF",IF(G30="Baja",7,IF(G30="Media",10,15)),IF(C30="EIF",IF(G30="Baja",5,IF(G30="Media",7,10)),"")))))) -> 3 | I30: =IF(H30="","",H30) -> 3 | J30: Santiago Torres
A31: 27 | B31: Registro de estudiantes nuevos por el docente | C31: ILF | D31: Es el lugar donde el sistema guarda los datos básicos del profesor: nombre completo, cédula y correo institucional (estos tres campos son el DET). Como esta información se maneja de forma uniforme, sin partes separadas, se cuenta como un solo bloque de datos (RET = 1). | E31: 3 | F31: 1 | G31: Baja | H31: =IF(OR(C31="",G31=""),"",IF(C31="EI",IF(G31="Baja",3,IF(G31="Media",4,6)),IF(C31="EO",IF(G31="Baja",4,IF(G31="Media",5,7)),IF(C31="EQ",IF(G31="Baja",3,IF(G31="Media",4,6)),IF(C31="ILF",IF(G31="Baja",7,IF(G31="Media",10,15)),IF(C31="EIF",IF(G31="Baja",5,IF(G31="Media",7,10)),"")))))) -> 7 | I31: =IF(H31="","",H31) -> 7 | J31: Simón Tabares
A32: 28 | B32: Registro de estudiantes nuevos por el docente | C32: EI | D32: El docente registra un estudiante nuevo con su nombre completo, cédula y correo institucional, y confirma con el botón "Registrar". El sistema valida que la cédula no esté repetida (DET = 5). Al guardar, el estudiante queda creado y automáticamente asociado a la asignatura, por lo que toca dos archivos: Estudiante y Matrícula (FTR = 2). | E32: 5 | F32: 2 | G32: Media | H32: =IF(OR(C32="",G32=""),"",IF(C32="EI",IF(G32="Baja",3,IF(G32="Media",4,6)),IF(C32="EO",IF(G32="Baja",4,IF(G32="Media",5,7)),IF(C32="EQ",IF(G32="Baja",3,IF(G32="Media",4,6)),IF(C32="ILF",IF(G32="Baja",7,IF(G32="Media",10,15)),IF(C32="EIF",IF(G32="Baja",5,IF(G32="Media",7,10)),"")))))) -> 4 | I32: =IF(H32="","",H32) -> 4 | J32: Simón Tabares
A33: 29 | B33: Crear actividad evaluativa por RA | C33: ILF | D33: Es el lugar donde el sistema guarda la información de cada acción de mejora: nombre, fecha tentativa, porcentaje, descripción, RA asociado y estado (estos seis campos son el DET). Como esta información se maneja de forma uniforme, sin partes separadas, se cuenta como un solo bloque de datos (RET = 1). | E33: 6 | F33: 1 | G33: Baja | H33: =IF(OR(C33="",G33=""),"",IF(C33="EI",IF(G33="Baja",3,IF(G33="Media",4,6)),IF(C33="EO",IF(G33="Baja",4,IF(G33="Media",5,7)),IF(C33="EQ",IF(G33="Baja",3,IF(G33="Media",4,6)),IF(C33="ILF",IF(G33="Baja",7,IF(G33="Media",10,15)),IF(C33="EIF",IF(G33="Baja",5,IF(G33="Media",7,10)),"")))))) -> 7 | I33: =IF(H33="","",H33) -> 7 | J33: Simón Tabares
A34: 30 | B34: Crear actividad evaluativa por RA | C34: EI | D34: El profesor registra una acción de mejora con nombre, fecha tentativa, porcentaje y descripción, y confirma con el botón de guardar. El sistema valida que la suma de los porcentajes no supere el 100% (DET = 6). Al guardar, la información queda en el archivo de Evaluación, y además se consulta el archivo de RA para confirmar la asociación correcta (FTR = 2). | E34: 6 | F34: 2 | G34: Media | H34: =IF(OR(C34="",G34=""),"",IF(C34="EI",IF(G34="Baja",3,IF(G34="Media",4,6)),IF(C34="EO",IF(G34="Baja",4,IF(G34="Media",5,7)),IF(C34="EQ",IF(G34="Baja",3,IF(G34="Media",4,6)),IF(C34="ILF",IF(G34="Baja",7,IF(G34="Media",10,15)),IF(C34="EIF",IF(G34="Baja",5,IF(G34="Media",7,10)),"")))))) -> 4 | I34: =IF(H34="","",H34) -> 4 | J34: Simón Tabares
... A36: 32 | B36: Activar/Inactivar actividad evaluativa por RA | C36: EI | D36: El profesor activa o inactiva una acción de mejora con un botón de cambio de estado, y el sistema muestra un mensaje de confirmación o error (DET = 2). Al guardar, la información se actualiza directamente en el archivo de Evaluación (FTR = 1). | E36: 2 | F36: 1 | G36: Baja | H36: =IF(OR(C36="",G36=""),"",IF(C36="EI",IF(G36="Baja",3,IF(G36="Media",4,6)),IF(C36="EO",IF(G36="Baja",4,IF(G36="Media",5,7)),IF(C36="EQ",IF(G36="Baja",3,IF(G36="Media",4,6)),IF(C36="ILF",IF(G36="Baja",7,IF(G36="Media",10,15)),IF(C36="EIF",IF(G36="Baja",5,IF(G36="Media",7,10)),"")))))) -> 3 | I36: =IF(H36="","",H36) -> 3 | J36: Simón Tabares
A37: 33 | B37: Registro de calificaciones y observaciones | C37: ILF | D37: Se guarda la información de cada calificación y observación. Los campos almacenados son estudiante, actividad evaluativa, nota, observación, fecha de registro y fecha de modificación. La información pertenece a un solo grupo lógico de calificaciones. | E37: 6 | F37: 2 | G37: Baja | H37: 7 | I37: 7 | J37: Jose Alejandro Valencia
A38: 34 | B38: Registro de calificaciones y observaciones | C38: EI | D38: Los campos requeridos para registrar o modificar una calificación son estudiante, actividad evaluativa, nota y observación. La función guarda la calificación y consulta la actividad evaluativa relacionada. | E38: 4 | F38: 2 | G38: Baja | H38: 3 | I38: 3 | J38: Jose Alejandro Valencia
A39: 35 | B39: Control de trazabilidad en fechas de registro | C39: EI | D39: Para registrar la trazabilidad se utilizan la calificación asociada, la fecha, la hora y el tipo de operación (registro o modificación). La función guarda estos datos en el historial y consulta la calificación relacionada. | E39: 4 | F39: 2 | G39: Baja | H39: 3 | I39: 3 | J39: Jose Alejandro Valencia
A40: 36 | B40: Cálculo y clasificación del nivel de logro | C40: EO | D40: Para cada estudiante y RA se muestra el resultado numérico calculado y su nivel de logro (Bajo, Medio, Alto o Sobresaliente). Para obtenerlo se consultan las calificaciones, las evaluaciones y los RA. | E40: 4 | F40: 3 | G40: Baja | H40: 4 | I40: 4 | J40: Jose Alejandro Valencia
A41: 37 | B41: Generación de estadísticas descriptivas | C41: EO | D41: Las estadísticas muestran por cada RA el promedio, el nivel de logro y la cantidad de estudiantes ubicada en cada nivel. Para generarlas se consultan las calificaciones, las evaluaciones y los RA. | E41: 4 | F41: 3 | G41: Baja | H41: 4 | I41: 4 | J41: Jose Alejandro Valencia
A42: 38 | B42: Generación de conclusiones y sugerencias de mejora | C42: EO | D42: Para cada RA se muestra el promedio, una conclusión sobre el desempeño y la sugerencia de mejora correspondiente. Para generar el resultado se consultan las calificaciones, las evaluaciones y los RA. | E42: 4 | F42: 3 | G42: Baja | H42: 4 | I42: 4 | J42: Jose Alejandro Valencia
...

Sheet Resumen
A1: RESUMEN DE LA ESTIMACIÓN
A3: Tipo | B3: Cantidad | C3: Puntos de Función
A4: EI | B4: =COUNTIF(Funciones!C5:C42,"EI") -> 21 | C4: =SUMIF(Funciones!C5:C42,"EI",Funciones!I5:I42) -> 69
A5: EO | B5: =COUNTIF(Funciones!C5:C42,"EO") -> 3 | C5: =SUMIF(Funciones!C5:C42,"EO",Funciones!I5:I42) -> 12
A6: EQ | B6: =COUNTIF(Funciones!C5:C42,"EQ") -> 4 | C6: =SUMIF(Funciones!C5:C42,"EQ",Funciones!I5:I42) -> 13
A7: ILF | B7: =COUNTIF(Funciones!C5:C42,"ILF") -> 9 | C7: =SUMIF(Funciones!C5:C42,"ILF",Funciones!I5:I42) -> 63
A8: EIF | B8: =COUNTIF(Funciones!C5:C42,"EIF") -> 0 | C8: =SUMIF(Funciones!C5:C42,"EIF",Funciones!I5:I42) -> 0
A9: TOTAL | B9: =SUM(B4:B8) -> 37 | C9: =SUM(C4:C8) -> 157
A12: Escala de pesos utilizada
A13: Tipo | B13: Baja | C13: Media | D13: Alta
A14: EI | B14: 3 | C14: 4 | D14: 6
A15: EO | B15: 4 | C15: 5 | D15: 7
A16: EQ | B16: 3 | C16: 4 | D16: 6
A17: ILF | B17: 7 | C17: 10 | D17: 15
A18: EIF | B18: 5 | C18: 7 | D18: 10

Sheet Ajuste
A1: FACTOR DE AJUSTE (VAF)
A2: Aspecto técnico que se evalúa | B2: Qué tanto influye esa característica | C2: Por qué asignaste ese valor | D2: Peso o grado de influencia asociado | E2: Resultado del valor × GSC
A3: Característica general del sistema | B3: Valor (0-5) | C3: Justificación | D3: GSC | E3: Contribución
A4: Comunicación de datos | B4: 4 | C4: SIGRA es una aplicación web totalmente interactiva: el navegador se comunica con la API por HTTPS y todo el trabajo se hace en línea, no hay procesos por lotes. Uso 4 y no 5 porque solo se maneja un protocolo (HTTP/HTTPS) y no hay integraciones con sistemas externos de la universidad. | D4: 1 | E4: =B4*D4 -> 4
A5: Procesamiento distribuido | B5: 3 | C5: El sistema está partido en frontend (Angular) y backend (API en Java), y los datos viajan en línea entre los dos en ambos sentidos. Pero todo el procesamiento real ocurre en un solo servidor: no hay varios nodos repartiéndose el trabajo ni balanceo de carga, por eso me quedo en 3 y no subo más. | D5: 2 | E5: =B5*D5 -> 6
A6: Rendimiento | B6: 3 | C6: Hay tiempos de respuesta escritos y medibles en los RNF (entre 3 y 5 segundos por operación, con 20 usuarios al mismo tiempo), o sea que sí es algo que toca cumplir durante toda la jornada. Aun así no es tiempo real ni carga alta, así que no exige un diseño especial de arquitectura pensado solo en rendimiento. | D6: 3 | E6: =B6*D6 -> 9
A7: Configuración altamente utilizada | B7: 1 | C7: El SRS dice que no hay restricciones importantes de infraestructura. El sistema corre en un servidor normal de la universidad, entonces sí existe una restricción (compartir ese servidor), pero es leve y no obliga a hacer nada especial en el diseño. | D7: 4 | E7: =B7*D7 -> 4
A8: Frecuencia de transacciones | B8: 1 | C8: Los picos de uso se dan en el cierre de notas y al final del semestre. Es un pico previsible, pero ocurre cada varios meses, no todos los días ni todas las semanas; el resto del tiempo el uso es bajo con unos 20 usuarios. | D8: 5 | E8: =B8*D8 -> 5
A9: Entrada de datos en línea | B9: 5 | C9: El 100% de la información entra en línea por formularios web: el catálogo (profesores, programas, asignaturas), los RA, las actividades evaluativas, las notas, las observaciones y las matrículas. No existe ningún proceso batch ni carga de archivos por lotes, así que va en el máximo. | D9: 6 | E9: =B9*D9 -> 30
A10: Eficiencia del usuario final | B10: 4 | C10: Se piden varias cosas de usabilidad al tiempo: diseño responsive, menús que cambian según el rol, filtros de búsqueda en casi todos los listados, mensajes de error claros y accesibilidad WCAG 2.1 AA (navegación por teclado, contraste y etiquetas ARIA). Son más de seis factores y además la accesibilidad es un requisito obligatorio, no un "sería bueno". | D10: 7 | E10: =B10*D10 -> 28
A11: Actualización en línea | B11: 3 | C11: Casi todos los archivos lógicos del sistema (Profesor, Programa, Asignatura, RA, Evaluación, Calificación, Matrícula) se actualizan en línea desde la interfaz. Hay respaldos y eliminación lógica para no perder datos, pero no hay un mecanismo especial de recuperación automática, por eso no subo a 4. | D11: 8 | E11: =B11*D11 -> 24
A12: Procesamiento complejo | B12: 2 | C12: Cuento dos factores: seguridad (RBAC validado en cada endpoint del backend y bloqueo de la cuenta tras 5 intentos fallidos) y lógica de negocio con varias reglas cruzadas (de 5 a 7 RA por asignatura, que los porcentajes de las actividades no pasen del 100%, el umbral del nivel de logro). No hay matemática pesada: los cálculos son promedios y comparaciones. | D12: 9 | E12: =B12*D12 -> 18
A13: Reusabilidad | B13: 1 | C13: Sí se reutiliza código dentro del mismo sistema (componentes de formulario, tablas con filtros, validaciones compartidas), pero nada está empaquetado ni documentado para usarlo en otro proyecto. Es reúso interno, que corresponde al nivel 1. | D13: 10 | E13: =B13*D13 -> 10
A14: Facilidad de instalación | B14: 1 | C14: Es un despliegue nuevo y no hay que migrar datos de un sistema viejo. Igual toca hacer una instalación: montar la base de datos, desplegar el backend y el frontend y crear el usuario administrador inicial. O sea, hay setup pero sin requisitos especiales de conversión. | D14: 11 | E14: =B14*D14 -> 11
A15: Facilidad de operación | B15: 2 | C15: Hay respaldos periódicos y un tiempo de recuperación definido (MTTR menor o igual a 4 horas), pero los ejecuta o los programa el administrador: no es automático ni desatendido. Sumo también que el sistema no maneja papel ni medios físicos. Entre las dos cosas da 2. | D15: 12 | E15: =B15*D15 -> 24
... A17: Facilidad de cambio | B17: 2 | C17: A favor: casi todos los listados tienen consultas flexibles con varios filtros combinables (programa, nombre, código, estado) y se pueden activar o inactivar registros en línea sin tocar código. En contra: las categorías de nivel de logro y sus umbrales están fijos en el código y el usuario no los puede parametrizar en esta versión. | D17: 14 | E17: =B17*D17 -> 28
A19: Ajuste de Complejidad Tecnica (ACT) | B19: =SUM(E4:E17) -> 201
A20: Complejidad del Proceso Ajustada (ACTA) | B20: =0.65+0.01*B19 -> 2.66
A21: Total de Puntos de Fucion Ajustados (PFA) | B21: =Resumen!C9*B20 -> 417.62

Sheet Calculo Esfuerzo
A2: CALCULO DE ESFUERZO
A4: Grupo de Trabajo (Nro Personas) | B4: 1
A5: Jornada Productiva | B5: 7
A6: Dias Laborables | B6: 20
A7: Productividad (Horas/PF) | B7: 10
A9: Esfuerzo Horas / Persona | B9: =Ajuste!B21/(1/B7) -> 4176.2
A10: Duración de Proyecto (h) | B10: =B9/B4 -> 4176.2
A11: Duración de Proyecto en Meses | B11: =B10/(B6*B5) -> 29.83

Sheet Instrucciones
A1: Objetivo | B1: Registrar y consolidar las funciones identificadas para calcular Puntos de Función.
A2: Paso 1 | B2: En 'Funciones', registre cada función o requisito analizado.
A3: Paso 2 | B3: Seleccione el tipo: EI, EO, EQ, ILF o EIF.
A4: Paso 3 | B4: Registre DET y FTR/RET según la metodología trabajada en clase.
A5: Paso 4 | B5: Seleccione la complejidad: Baja, Media o Alta.
A6: Paso 5 | B6: El peso y los Puntos de Función se calculan automáticamente.
A7: Paso 6 | B7: Revise el total en 'Resumen'.
A8: Opcional | B8: Si utilizan factor de ajuste, complete la hoja 'Ajuste' con valores de 0 a 5 y justifique cada valoración.
A9: Criterio | B9: No clasifique por pantalla o por cantidad de campos. Justifique la función, la frontera y los grupos lógicos de datos.
A10: Nota | B10: La plantilla usa la matriz clásica de pesos: EI 3/4/6, EO 4/5/7, EQ 3/4/6, ILF 7/10/15 y EIF 5/7/10.
